Workbook

Sheet Dashboard
A1: TOTALS | I1: EARNINGS
A2: Type | B2: Total Open | C2: %Portfolio | I2: Type | J2: Total Open | K2: % Open
A3: CASH | B3: 761 | C3: =if($A3=0,"",$B3/$F$14) -> 0.098446515 | I3: CEDEAR | J3: =IFNA(CEDEARs!AF22,0) -> 1074.7897 | K3: =J3/F14 -> 0.13903982
A4: CEDEAR | B4: =IFNA(CEDEARs!AF20,0) -> 3650.6595 | C4: =if($A4=0,"",$B4/$F$14) -> 0.47226637 | I4: BOND | J4: =IFNA(Bonds!AL20,0) -> 863.47705 | K4: =J4/F14 -> 0.11170343
A5: BOND | B5: =IFNA(Bonds!AL18,0) -> 1340.4354 | C5: =if($A5=0,"",$B5/$F$14) -> 0.17340498 | I5: ON | J5: =IFNA(ONs!AH20,0) -> 283.94694 | K5: =$J5/$F$14 -> 0.036732703
A6: ON | B6: =IFNA(ONs!AH18,0) -> 1533.8601 | C6: =if($A6=0,"",$B6/$F$14) -> 0.19842731 | I6: FCI | J6: =IFNA(FCIs!AH20,0) -> 0 | K6: =$J6/$F$14 -> 0
A7: FCI | B7: =IFNA(FCIs!AH18,0) -> 0 | C7: =if($A7=0,"",$B7/$F$14) -> 0 | I7: Crypto | J7: =IFNA(Cryptos!Y22,0) -> 175.00669 | K7: =$J7/$F$14 -> 0.022639683
A8: Crypto | B8: =IFNA(Cryptos!Y20,0) -> 444.1307 | C8: =if($A8=0,"",$B8/$F$14) -> 0.057454822 | K8: =$J8/$F$14 -> 0
C9: =if($A9=0,"",$B9/$F$14) | K9: =$J9/$F$14 -> 0
C10: =if($A10=0,"",$B10/$F$14) | K10: =$J10/$F$14 -> 0
C11: =if($A11=0,"",$B11/$F$14) | K11: =$J11/$F$14 -> 0
C12: =if($A12=0,"",$B12/$F$14) | K12: =$J12/$F$14 -> 0
E14: Total U$D | F14: =SUM(B3:B12) -> 7730.0857 | I14: Total U$D | J14: =SUM(J3:J12) -> 2397.2204 | K14: =J14/F14 -> 0.31011563
K15: a

Sheet CEDEARs
A1: ID | B1: Ticker | C1: Apertura | D1: Estado | E1: Cierre | F1: Dias | G1: Moneda | H1: Unidades | I1: Valor Compra | J1: Valor Venta | K1: Valor Actual | L1: Total Compra | M1: CCL Compra | N1: TC USD | O1: Total Venta | P1: CCL Venta | Q1: TV USD | R1: GAN USD% | S1: GAN USD | T1: Ganancias (%) | U1: Ganancias Bruta | W1: CEDEAR Ticker | X1: Unidades | Y1: % Cartera | Z1: PPC | AA1: Total (Abierto) | AB1: Ganancias (%) | AC1: Ganancias Tot
A2: IOL | B2: AAPL | C2: 44939 | D2: ABIERTA | F2: =if($B2=0,"...", IF($E2=0,today()-$C2,$E2-$C2)) -> 1057 | G2: PESOS | H2: 20 | I2: 4374 | K2: =IFERROR(__xludf.DUMMYFUNCTION("if(B2=0,""..."",IF($G2=""PESOS"",GOOGLEFINANCE(""BCBA:""&$B2),GOOGLEFINANCE($B2)/20))"),21040.0) -> 21040 | L2: =if(B2=0,"...",$H2*I2) -> 87480 | M2: =VLOOKUP(C2,CCLHistory!$A$3:$B84,2,FALSE) -> 349,26 | N2: =L2/IF(G2="USD",1,M2) -> 250.47243 | O2: =if(B2=0,"...",$H2*(IF(D2="ABIERTA",K2,J2)*(1-VLOOKUP(A2,Config!$A$3:$B$5,2,FALSE)))) -> 420778.96 | P2: =IF(D2="ABIERTA",Config!$D$4,VLOOKUP(E2,CCLHistory!$A$6:$B84,2,FALSE)) -> 1269 | Q2: =O2/IF(G2="USD",1,P2) -> 331.5831 | R2: =if(B2=0,"...",Q2/N2-1) -> 0.32383076 | S2: =if(B2=0,"...",Q2-N2) -> 81.110677 | T2: =if(B2=0,"...",O2/L2-1) -> 3.8100018 | U2: =if(B2=0,"...",O2-L2) -> 333298.96 | W2: {=Unique(B2:B84)} -> AAPL | X2: =if(W2=0,"...",sumifs($H$2:$H84,$B$2:$B84,W2,$D$2:$D84,"ABIERTA")) -> 32 | Y2: =if(W2=0,"",AA2/$AF$20) -> 0.13686806 | Z2: =if(X2=0,"...",if(W2=0,"...",sumifs($N$2:$N84,$B$2:$B84,W2,$D$2:$D84,"ABIERTA")/X2)) -> 11.417888 | AA2: =if(W2=0,"...",sumifs($Q$2:$Q84,$B$2:$B84,W2,$D$2:$D84,"ABIERTA")) -> 499.6587 | AB2: =if(X2=0,"...",if(W2=0,"...",AC2/(AA2-AC2))) -> 0.36753259 | AC2: =if(X2=0,"...",if(W2=0,"...",sumifs($S$2:$S84,$B$2:$B84,W2,$D$2:$D84,"ABIERTA"))) -> 134.28627
A3: IOL | B3: AAPL | C3: 45301 | D3: ABIERTA | F3: =if($B3=0,"...", IF($E3=0,today()-$C3,$E3-$C3)) -> 695 | G3: USD | H3: 10 | I3: 9.625 | K3: =IFERROR(__xludf.DUMMYFUNCTION("if(B3=0,""..."",IF($G3=""PESOS"",GOOGLEFINANCE(""BCBA:""&$B3),GOOGLEFINANCE($B3)/20))"),14.007) -> 14.007 | L3: =if(B3=0,"...",$H3*I3) -> 96.25 | M3: =VLOOKUP(C3,CCLHistory!$A$3:$B84,2,FALSE) -> 1182.72 | N3: =L3/IF(G3="USD",1,M3) -> 96.25 | O3: =if(B3=0,"...",$H3*(IF(D3="ABIERTA",K3,J3)*(1-VLOOKUP(A3,Config!$A$3:$B$5,2,FALSE)))) -> 140.063 | P3: =IF(D3="ABIERTA",Config!$D$4,VLOOKUP(E3,CCLHistory!$A$6:$B84,2,FALSE)) -> 1269 | Q3: =O3/IF(G3="USD",1,P3) -> 140.063 | R3: =if(B3=0,"...",Q3/N3-1) -> 0.45519996 | S3: =if(B3=0,"...",Q3-N3) -> 43.812996 | T3: =if(B3=0,"...",O3/L3-1) -> 0.45519996 | U3: =if(B3=0,"...",O3-L3) -> 43.812996 | W3: KO | X3: =if(W3=0,"...",sumifs($H$2:$H85,$B$2:$B85,W3,$D$2:$D85,"ABIERTA")) -> 128 | Y3: =if(W3=0,"",AA3/$AF$20) -> 0.58627406 | Z3: =if(X3=0,"...",if(W3=0,"...",sumifs($N$2:$N85,$B$2:$B85,W3,$D$2:$D85,"ABIERTA")/X3)) -> 12.214398 | AA3: =if(W3=0,"...",sumifs($Q$2:$Q85,$B$2:$B85,W3,$D$2:$D85,"ABIERTA")) -> 2140.287 | AB3: =if(X3=0,"...",if(W3=0,"...",AC3/(AA3-AC3))) -> 0.36895749 | AC3: =if(X3=0,"...",if(W3=0,"...",sumifs($S$2:$S85,$B$2:$B85,W3,$D$2:$D85,"ABIERTA"))) -> 576.844
A4: IOL | B4: AAPL | C4: 45210 | D4: ABIERTA | F4: =if($B4=0,"...", IF($E4=0,today()-$C4,$E4-$C4)) -> 786 | G4: USD | H4: 2 | I4: 9.325 | K4: =IFERROR(__xludf.DUMMYFUNCTION("if(B4=0,""..."",IF($G4=""PESOS"",GOOGLEFINANCE(""BCBA:""&$B4),GOOGLEFINANCE($B4)/20))"),14.007) -> 14.007 | L4: =if(B4=0,"...",$H4*I4) -> 18.65 | M4: =VLOOKUP(C4,CCLHistory!$A$3:$B84,2,FALSE) -> 944,94 | N4: =L4/IF(G4="USD",1,M4) -> 18.65 | O4: =if(B4=0,"...",$H4*(IF(D4="ABIERTA",K4,J4)*(1-VLOOKUP(A4,Config!$A$3:$B$5,2,FALSE)))) -> 28.012599 | P4: =IF(D4="ABIERTA",Config!$D$4,VLOOKUP(E4,CCLHistory!$A$6:$B84,2,FALSE)) -> 1269 | Q4: =O4/IF(G4="USD",1,P4) -> 28.012599 | R4: =if(B4=0,"...",Q4/N4-1) -> 0.50201605 | S4: =if(B4=0,"...",Q4-N4) -> 9.3625993 | T4: =if(B4=0,"...",O4/L4-1) -> 0.50201605 | U4: =if(B4=0,"...",O4-L4) -> 9.3625993 | W4: DISN | X4: =if(W4=0,"...",sumifs($H$2:$H86,$B$2:$B86,W4,$D$2:$D86,"ABIERTA")) -> 6 | Y4: =if(W4=0,"",AA4/$AF$20) -> 0.017159809 | Z4: =if(X4=0,"...",if(W4=0,"...",sumifs($N$2:$N86,$B$2:$B86,W4,$D$2:$D86,"ABIERTA")/X4)) -> 7.6472113 | AA4: =if(W4=0,"...",sumifs($Q$2:$Q86,$B$2:$B86,W4,$D$2:$D86,"ABIERTA")) -> 62.644622 | AB4: =if(X4=0,"...",if(W4=0,"...",AC4/(AA4-AC4))) -> 0.36530428 | AC4: =if(X4=0,"...",if(W4=0,"...",sumifs($S$2:$S86,$B$2:$B86,W4,$D$2:$D86,"ABIERTA"))) -> 16.761354
A5: IOL | B5: KO | C5: 44138 | D5: ABIERTA | F5: =if($B5=0,"...", IF($E5=0,today()-$C5,$E5-$C5)) -> 1858 | G5: PESOS | H5: 1 | I5: 1477 | K5: =IFERROR(__xludf.DUMMYFUNCTION("if(B5=0,""..."",GOOGLEFINANCE(""BCBA:""&B5))"),21220.0) -> 21220 | L5: =if(B5=0,"...",$H5*I5) -> 1477 | M5: =VLOOKUP(C5,CCLHistory!$A$3:$B84,2,FALSE) -> 153,9 | N5: =L5/IF(G5="USD",1,M5) -> 9.597141 | O5: =if(B5=0,"...",$H5*(IF(D5="ABIERTA",K5,J5)*(1-VLOOKUP(A5,Config!$A$3:$B$5,2,FALSE)))) -> 21218.939 | P5: =IF(D5="ABIERTA",Config!$D$4,VLOOKUP(E5,CCLHistory!$A$6:$B84,2,FALSE)) -> 1269 | Q5: =O5/IF(G5="USD",1,P5) -> 16.720992 | R5: =if(B5=0,"...",Q5/N5-1) -> 0.74228889 | S5: =if(B5=0,"...",Q5-N5) -> 7.1238511 | T5: =if(B5=0,"...",O5/L5-1) -> 13.366242 | U5: =if(B5=0,"...",O5-L5) -> 19741.939 | W5: DIA | X5: =if(W5=0,"...",sumifs($H$2:$H87,$B$2:$B87,W5,$D$2:$D87,"ABIERTA")) -> 19 | Y5: =if(W5=0,"",AA5/$AF$20) -> 0.14821327 | Z5: =if(X5=0,"...",if(W5=0,"...",sumifs($N$2:$N87,$B$2:$B87,W5,$D$2:$D87,"ABIERTA")/X5)) -> 20.211455 | AA5: =if(W5=0,"...",sumifs($Q$2:$Q87,$B$2:$B87,W5,$D$2:$D87,"ABIERTA")) -> 541.07618 | AB5: =if(X5=0,"...",if(W5=0,"...",AC5/(AA5-AC5))) -> 0.40898782 | AC5: =if(X5=0,"...",if(W5=0,"...",sumifs($S$2:$S87,$B$2:$B87,W5,$D$2:$D87,"ABIERTA"))) -> 157.05854
A6: IOL | B6: KO | C6: 44148 | D6: ABIERTA | F6: =if($B6=0,"...", IF($E6=0,today()-$C6,$E6-$C6)) -> 1848 | G6: PESOS | H6: 1 | I6: 1605 | K6: =IFERROR(__xludf.DUMMYFUNCTION("if(B6=0,""..."",GOOGLEFINANCE(""BCBA:""&B6))"),21220.0) -> 21220 | L6: =if(B6=0,"...",$H6*I6) -> 1605 | M6: =VLOOKUP(C6,CCLHistory!$A$3:$B84,2,FALSE) -> 148,74 | N6: =L6/IF(G6="USD",1,M6) -> 10.790641 | O6: =if(B6=0,"...",$H6*(IF(D6="ABIERTA",K6,J6)*(1-VLOOKUP(A6,Config!$A$3:$B$5,2,FALSE)))) -> 21218.939 | P6: =IF(D6="ABIERTA",Config!$D$4,VLOOKUP(E6,CCLHistory!$A$6:$B84,2,FALSE)) -> 1269 | Q6: =O6/IF(G6="USD",1,P6) -> 16.720992 | R6: =if(B6=0,"...",Q6/N6-1) -> 0.54958278 | S6: =if(B6=0,"...",Q6-N6) -> 5.9303507 | T6: =if(B6=0,"...",O6/L6-1) -> 12.220523 | U6: =if(B6=0,"...",O6-L6) -> 19613.939 | W6: SPY | X6: =if(W6=0,"...",sumifs($H$2:$H88,$B$2:$B88,W6,$D$2:$D88,"ABIERTA")) -> 10 | Y6: =if(W6=0,"",AA6/$AF$20) -> 0.1114848 | Z6: =if(X6=0,"...",if(W6=0,"...",sumifs($N$2:$N88,$B$2:$B88,W6,$D$2:$D88,"ABIERTA")/X6)) -> 21.715348 | AA6: =if(W6=0,"...",sumifs($Q$2:$Q88,$B$2:$B88,W6,$D$2:$D88,"ABIERTA")) -> 406.99305 | AB6: =if(X6=0,"...",if(W6=0,"...",AC6/(AA6-AC6))) -> 0.87421843 | AC6: =if(X6=0,"...",if(W6=0,"...",sumifs($S$2:$S88,$B$2:$B88,W6,$D$2:$D88,"ABIERTA"))) -> 189.83957
A7: IOL | B7: KO | C7: 44151 | D7: ABIERTA | F7: =if($B7=0,"...", IF($E7=0,today()-$C7,$E7-$C7)) -> 1845 | G7: PESOS | H7: 1 | I7: 1580 | K7: =IFERROR(__xludf.DUMMYFUNCTION("if(B7=0,""..."",GOOGLEFINANCE(""BCBA:""&B7))"),21220.0) -> 21220 | L7: =if(B7=0,"...",$H7*I7) -> 1580 | M7: =VLOOKUP(C7,CCLHistory!$A$3:$B84,2,FALSE) -> 148,56 | N7: =L7/IF(G7="USD",1,M7) -> 10.635433 | O7: =if(B7=0,"...",$H7*(IF(D7="ABIERTA",K7,J7)*(1-VLOOKUP(A7,Config!$A$3:$B$5,2,FALSE)))) -> 21218.939 | P7: =IF(D7="ABIERTA",Config!$D$4,VLOOKUP(E7,CCLHistory!$A$6:$B84,2,FALSE)) -> 1269 | Q7: =O7/IF(G7="USD",1,P7) -> 16.720992 | R7: =if(B7=0,"...",Q7/N7-1) -> 0.57219658 | S7: =if(B7=0,"...",Q7-N7) -> 6.0855586 | T7: =if(B7=0,"...",O7/L7-1) -> 12.429708 | U7: =if(B7=0,"...",O7-L7) -> 19638.939 | W7: JNJ | X7: =if(W7=0,"...",sumifs($H$2:$H89,$B$2:$B89,W7,$D$2:$D89,"ABIERTA")) -> 0 | Y7: =if(W7=0,"",AA7/$AF$20) -> 0 | Z7: =if(X7=0,"...",if(W7=0,"...",sumifs($N$2:$N89,$B$2:$B89,W7,$D$2:$D89,"ABIERTA")/X7)) -> ... | AA7: =if(W7=0,"...",sumifs($Q$2:$Q89,$B$2:$B89,W7,$D$2:$D89,"ABIERTA")) -> 0 | AB7: =if(X7=0,"...",if(W7=0,"...",AC7/(AA7-AC7))) -> ... | AC7: =if(X7=0,"...",if(W7=0,"...",sumifs($S$2:$S89,$B$2:$B89,W7,$D$2:$D89,"ABIERTA"))) -> ...
A8: IOL | B8: KO | C8: 44175 | D8: ABIERTA | F8: =if($B8=0,"...", IF($E8=0,today()-$C8,$E8-$C8)) -> 1821 | G8: PESOS | H8: 3 | I8: 1552 | K8: =IFERROR(__xludf.DUMMYFUNCTION("if(B8=0,""..."",GOOGLEFINANCE(""BCBA:""&B8))"),21220.0) -> 21220 | L8: =if(B8=0,"...",$H8*I8) -> 4656 | M8: =VLOOKUP(C8,CCLHistory!$A$3:$B84,2,FALSE) -> 141,38 | N8: =L8/IF(G8="USD",1,M8) -> 32.932522 | O8: =if(B8=0,"...",$H8*(IF(D8="ABIERTA",K8,J8)*(1-VLOOKUP(A8,Config!$A$3:$B$5,2,FALSE)))) -> 63656.817 | P8: =IF(D8="ABIERTA",Config!$D$4,VLOOKUP(E8,CCLHistory!$A$6:$B84,2,FALSE)) -> 1269 | Q8: =O8/IF(G8="USD",1,P8) -> 50.162976 | R8: =if(B8=0,"...",Q8/N8-1) -> 0.52320481 | S8: =if(B8=0,"...",Q8-N8) -> 17.230454 | T8: =if(B8=0,"...",O8/L8-1) -> 12.671997 | U8: =if(B8=0,"...",O8-L8) -> 59000.817 | W8: BRKB | X8: =if(W8=0,"...",sumifs($H$2:$H90,$B$2:$B90,W8,$D$2:$D90,"ABIERTA")) -> 0 | Y8: =if(W8=0,"",AA8/$AF$20) -> 0 | Z8: =if(X8=0,"...",if(W8=0,"...",sumifs($N$2:$N90,$B$2:$B90,W8,$D$2:$D90,"ABIERTA")/X8)) -> ... | AA8: =if(W8=0,"...",sumifs($Q$2:$Q90,$B$2:$B90,W8,$D$2:$D90,"ABIERTA")) -> 0 | AB8: =if(X8=0,"...",if(W8=0,"...",AC8/(AA8-AC8))) -> ... | AC8: =if(X8=0,"...",if(W8=0,"...",sumifs($S$2:$S90,$B$2:$B90,W8,$D$2:$D90,"ABIERTA"))) -> ...
A9: IOL | B9: KO | C9: 44228 | D9: ABIERTA | F9: =if($B9=0,"...", IF($E9=0,today()-$C9,$E9-$C9)) -> 1768 | G9: PESOS | H9: 3 | I9: 1510 | K9: =IFERROR(__xludf.DUMMYFUNCTION("if(B9=0,""..."",GOOGLEFINANCE(""BCBA:""&B9))"),21220.0) -> 21220 | L9: =if(B9=0,"...",$H9*I9) -> 4530 | M9: =VLOOKUP(C9,CCLHistory!$A$3:$B84,2,FALSE) -> 154,69 | N9: =L9/IF(G9="USD",1,M9) -> 29.284375 | O9: =if(B9=0,"...",$H9*(IF(D9="ABIERTA",K9,J9)*(1-VLOOKUP(A9,Config!$A$3:$B$5,2,FALSE)))) -> 63656.817 | P9: =IF(D9="ABIERTA",Config!$D$4,VLOOKUP(E9,CCLHistory!$A$6:$B84,2,FALSE)) -> 1269 | Q9: =O9/IF(G9="USD",1,P9) -> 50.162976 | R9: =if(B9=0,"...",Q9/N9-1) -> 0.71296044 | S9: =if(B9=0,"...",Q9-N9) -> 20.878601 | T9: =if(B9=0,"...",O9/L9-1) -> 13.052277 | U9: =if(B9=0,"...",O9-L9) -> 59126.817 | W9: HMY | X9: =if(W9=0,"...",sumifs($H$2:$H91,$B$2:$B91,W9,$D$2:$D91,"ABIERTA")) -> 0 | Y9: =if(W9=0,"",AA9/$AF$20) -> 0 | Z9: =if(X9=0,"...",if(W9=0,"...",sumifs($N$2:$N91,$B$2:$B91,W9,$D$2:$D91,"ABIERTA")/X9)) -> ... | AA9: =if(W9=0,"...",sumifs($Q$2:$Q91,$B$2:$B91,W9,$D$2:$D91,"ABIERTA")) -> 0 | AB9: =if(X9=0,"...",if(W9=0,"...",AC9/(AA9-AC9))) -> ... | AC9: =if(X9=0,"...",if(W9=0,"...",sumifs($S$2:$S91,$B$2:$B91,W9,$D$2:$D91,"ABIERTA"))) -> ...
A10: IOL | B10: KO | C10: 44245 | D10: ABIERTA | F10: =if($B10=0,"...", IF($E10=0,today()-$C10,$E10-$C10)) -> 1751 | G10: PESOS | H10: 3 | I10: 1533 | K10: =IFERROR(__xludf.DUMMYFUNCTION("if(B10=0,""..."",GOOGLEFINANCE(""BCBA:""&B10))"),21220.0) -> 21220 | L10: =if(B10=0,"...",$H10*I10) -> 4599 | M10: =VLOOKUP(C10,CCLHistory!$A$3:$B84,2,FALSE) -> 145,18 | N10: =L10/IF(G10="USD",1,M10) -> 31.677917 | O10: =if(B10=0,"...",$H10*(IF(D10="ABIERTA",K10,J10)*(1-VLOOKUP(A10,Config!$A$3:$B$5,2,FALSE)))) -> 63656.817 | P10: =IF(D10="ABIERTA",Config!$D$4,VLOOKUP(E10,CCLHistory!$A$6:$B84,2,FALSE)) -> 1269 | Q10: =O10/IF(G10="USD",1,P10) -> 50.162976 | R10: =if(B10=0,"...",Q10/N10-1) -> 0.5835314 | S10: =if(B10=0,"...",Q10-N10) -> 18.485059 | T10: =if(B10=0,"...",O10/L10-1) -> 12.841447 | U10: =if(B10=0,"...",O10-L10) -> 59057.817 | W10: INTC | X10: =if(W10=0,"...",sumifs($H$2:$H92,$B$2:$B92,W10,$D$2:$D92,"ABIERTA")) -> 0 | Y10: =if(W10=0,"",AA10/$AF$20) -> 0 | Z10: =if(X10=0,"...",if(W10=0,"...",sumifs($N$2:$N92,$B$2:$B92,W10,$D$2:$D92,"ABIERTA")/X10)) -> ... | AA10: =if(W10=0,"...",sumifs($Q$2:$Q92,$B$2:$B92,W10,$D$2:$D92,"ABIERTA")) -> 0 | AB10: =if(X10=0,"...",if(W10=0,"...",AC10/(AA10-AC10))) -> ... | AC10: =if(X10=0,"...",if(W10=0,"...",sumifs($S$2:$S92,$B$2:$B92,W10,$D$2:$D92,"ABIERTA"))) -> ...
A11: IOL | B11: KO | C11: 44426 | D11: ABIERTA | F11: =if($B11=0,"...", IF($E11=0,today()-$C11,$E11-$C11)) -> 1570 | G11: PESOS | H11: 1 | I11: 2043 | K11: =IFERROR(__xludf.DUMMYFUNCTION("if(B11=0,""..."",GOOGLEFINANCE(""BCBA:""&B11))"),21220.0) -> 21220 | L11: =if(B11=0,"...",$H11*I11) -> 2043 | M11: =VLOOKUP(C11,CCLHistory!$A$3:$B84,2,FALSE) -> 177,04 | N11: =L11/IF(G11="USD",1,M11) -> 11.539765 | O11: =if(B11=0,"...",$H11*(IF(D11="ABIERTA",K11,J11)*(1-VLOOKUP(A11,Config!$A$3:$B$5,2,FALSE)))) -> 21218.939 | P11: =IF(D11="ABIERTA",Config!$D$4,VLOOKUP(E11,CCLHistory!$A$6:$B84,2,FALSE)) -> 1269 | Q11: =O11/IF(G11="USD",1,P11) -> 16.720992 | R11: =if(B11=0,"...",Q11/N11-1) -> 0.44898896 | S11: =if(B11=0,"...",Q11-N11) -> 5.1812271 | T11: =if(B11=0,"...",O11/L11-1) -> 9.3861669 | U11: =if(B11=0,"...",O11-L11) -> 19175.939 | W11: MELI | X11: =if(W11=0,"...",sumifs($H$2:$H93,$B$2:$B93,W11,$D$2:$D93,"ABIERTA")) -> 0 | Y11: =if(W11=0,"",AA11/$AF$20) -> 0 | Z11: =if(X11=0,"...",if(W11=0,"...",sumifs($N$2:$N93,$B$2:$B93,W11,$D$2:$D93,"ABIERTA")/X11)) -> ... | AA11: =if(W11=0,"...",sumifs($Q$2:$Q93,$B$2:$B93,W11,$D$2:$D93,"ABIERTA")) -> 0 | AB11: =if(X11=0,"...",if(W11=0,"...",AC11/(AA11-AC11))) -> ... | AC11: =if(X11=0,"...",if(W11=0,"...",sumifs($S$2:$S93,$B$2:$B93,W11,$D$2:$D93,"ABIERTA"))) -> ...
A12: IOL | B12: KO | C12: 44449 | D12: ABIERTA | F12: =if($B12=0,"...", IF($E12=0,today()-$C12,$E12-$C12)) -> 1547 | G12: PESOS | H12: 5 | I12: 2012 | K12: =IFERROR(__xludf.DUMMYFUNCTION("if(B12=0,""..."",GOOGLEFINANCE(""BCBA:""&B12))"),21220.0) -> 21220 | L12: =if(B12=0,"...",$H12*I12) -> 10060 | M12: =VLOOKUP(C12,CCLHistory!$A$3:$B84,2,FALSE) -> 183,42 | N12: =L12/IF(G12="USD",1,M12) -> 54.8468 | O12: =if(B12=0,"...",$H12*(IF(D12="ABIERTA",K12,J12)*(1-VLOOKUP(A12,Config!$A$3:$B$5,2,FALSE)))) -> 106094.7 | P12: =IF(D12="ABIERTA",Config!$D$4,VLOOKUP(E12,CCLHistory!$A$6:$B84,2,FALSE)) -> 1269 | Q12: =O12/IF(G12="USD",1,P12) -> 83.604961 | R12: =if(B12=0,"...",Q12/N12-1) -> 0.52433617 | S12: =if(B12=0,"...",Q12-N12) -> 28.758161 | T12: =if(B12=0,"...",O12/L12-1) -> 9.5461923 | U12: =if(B12=0,"...",O12-L12) -> 96034.695 | W12: MSFT | X12: =if(W12=0,"...",sumifs($H$2:$H94,$B$2:$B94,W12,$D$2:$D94,"ABIERTA")) -> 0 | Y12: =if(W12=0,"",AA12/$AF$20) -> 0 | Z12: =if(X12=0,"...",if(W12=0,"...",sumifs($N$2:$N94,$B$2:$B94,W12,$D$2:$D94,"ABIERTA")/X12)) -> ... | AA12: =if(W12=0,"...",sumifs($Q$2:$Q94,$B$2:$B94,W12,$D$2:$D94,"ABIERTA")) -> 0 | AB12: =if(X12=0,"...",if(W12=0,"...",AC12/(AA12-AC12))) -> ... | AC12: =if(X12=0,"...",if(W12=0,"...",sumifs($S$2:$S94,$B$2:$B94,W12,$D$2:$D94,"ABIERTA"))) -> ...
A13: IOL | B13: KO | C13: 44459 | D13: ABIERTA | F13: =if($B13=0,"...", IF($E13=0,today()-$C13,$E13-$C13)) -> 1537 | G13: PESOS | H13: 2 | I13: 1975.5 | K13: =IFERROR(__xludf.DUMMYFUNCTION("if(B13=0,""..."",GOOGLEFINANCE(""BCBA:""&B13))"),21220.0) -> 21220 | L13: =if(B13=0,"...",$H13*I13) -> 3951 | M13: =VLOOKUP(C13,CCLHistory!$A$3:$B84,2,FALSE) -> 185,38 | N13: =L13/IF(G13="USD",1,M13) -> 21.312979 | O13: =if(B13=0,"...",$H13*(IF(D13="ABIERTA",K13,J13)*(1-VLOOKUP(A13,Config!$A$3:$B$5,2,FALSE)))) -> 42437.878 | P13: =IF(D13="ABIERTA",Config!$D$4,VLOOKUP(E13,CCLHistory!$A$6:$B84,2,FALSE)) -> 1269 | Q13: =O13/IF(G13="USD",1,P13) -> 33.441984 | R13: =if(B13=0,"...",Q13/N13-1) -> 0.56909011 | S13: =if(B13=0,"...",Q13-N13) -> 12.129005 | T13: =if(B13=0,"...",O13/L13-1) -> 9.7410473 | U13: =if(B13=0,"...",O13-L13) -> 38486.878 | W13: SPOT | X13: =if(W13=0,"...",sumifs($H$2:$H95,$B$2:$B95,W13,$D$2:$D95,"ABIERTA")) -> 0 | Y13: =if(W13=0,"",AA13/$AF$20) -> 0 | Z13: =if(X13=0,"...",if(W13=0,"...",sumifs($N$2:$N95,$B$2:$B95,W13,$D$2:$D95,"ABIERTA")/X13)) -> ... | AA13: =if(W13=0,"...",sumifs($Q$2:$Q95,$B$2:$B95,W13,$D$2:$D95,"ABIERTA")) -> 0 | AB13: =if(X13=0,"...",if(W13=0,"...",AC13/(AA13-AC13))) -> ... | AC13: =if(X13=0,"...",if(W13=0,"...",sumifs($S$2:$S95,$B$2:$B95,W13,$D$2:$D95,"ABIERTA"))) -> ...
A14: IOL | B14: KO | C14: 44649 | D14: ABIERTA | F14: =if($B14=0,"...", IF($E14=0,today()-$C14,$E14-$C14)) -> 1347 | G14: PESOS | H14: 32 | I14: 2454 | K14: =IFERROR(__xludf.DUMMYFUNCTION("if(B14=0,""..."",GOOGLEFINANCE(""BCBA:""&B14))"),21220.0) -> 21220 | L14: =if(B14=0,"...",$H14*I14) -> 78528 | M14: =VLOOKUP(C14,CCLHistory!$A$3:$B84,2,FALSE) -> 191,52 | N14: =L14/IF(G14="USD",1,M14) -> 410.02506 | O14: =if(B14=0,"...",$H14*(IF(D14="ABIERTA",K14,J14)*(1-VLOOKUP(A14,Config!$A$3:$B$5,2,FALSE)))) -> 679006.05 | P14: =IF(D14="ABIERTA",Config!$D$4,VLOOKUP(E14,CCLHistory!$A$6:$B84,2,FALSE)) -> 1269 | Q14: =O14/IF(G14="USD",1,P14) -> 535.07175 | R14: =if(B14=0,"...",Q14/N14-1) -> 0.30497327 | S14: =if(B14=0,"...",Q14-N14) -> 125.04669 | T14: =if(B14=0,"...",O14/L14-1) -> 7.6466744 | U14: =if(B14=0,"...",O14-L14) -> 600478.05 | W14: WMT | X14: =if(W14=0,"...",sumifs($H$2:$H96,$B$2:$B96,W14,$D$2:$D96,"ABIERTA")) -> 0 | Y14: =if(W14=0,"",AA14/$AF$20) -> 0 | Z14: =if(X14=0,"...",if(W14=0,"...",sumifs($N$2:$N96,$B$2:$B96,W14,$D$2:$D96,"ABIERTA")/X14)) -> ... | AA14: =if(W14=0,"...",sumifs($Q$2:$Q96,$B$2:$B96,W14,$D$2:$D96,"ABIERTA")) -> 0 | AB14: =if(X14=0,"...",if(W14=0,"...",AC14/(AA14-AC14))) -> ... | AC14: =if(X14=0,"...",if(W14=0,"...",sumifs($S$2:$S96,$B$2:$B96,W14,$D$2:$D96,"ABIERTA"))) -> ...
A15: IOL | B15: KO | C15: 44687 | D15: ABIERTA | F15: =if($B15=0,"...", IF($E15=0,today()-$C15,$E15-$C15)) -> 1309 | G15: PESOS | H15: 11 | I15: 2650 | K15: =IFERROR(__xludf.DUMMYFUNCTION("if(B15=0,""..."",GOOGLEFINANCE(""BCBA:""&B15))"),21220.0) -> 21220 | L15: =if(B15=0,"...",$H15*I15) -> 29150 | M15: =VLOOKUP(C15,CCLHistory!$A$3:$B84,2,FALSE) -> 208,84 | N15: =L15/IF(G15="USD",1,M15) -> 139.58054 | O15: =if(B15=0,"...",$H15*(IF(D15="ABIERTA",K15,J15)*(1-VLOOKUP(A15,Config!$A$3:$B$5,2,FALSE)))) -> 233408.33 | P15: =IF(D15="ABIERTA",Config!$D$4,VLOOKUP(E15,CCLHistory!$A$6:$B84,2,FALSE)) -> 1269 | Q15: =O15/IF(G15="USD",1,P15) -> 183.93091 | R15: =if(B15=0,"...",Q15/N15-1) -> 0.31774038 | S15: =if(B15=0,"...",Q15-N15) -> 44.350373 | T15: =if(B15=0,"...",O15/L15-1) -> 7.0071468 | U15: =if(B15=0,"...",O15-L15) -> 204258.33 | X15: =if(W15=0,"...",sumifs($H$2:$H97,$B$2:$B97,W15,$D$2:$D97,"ABIERTA")) -> ... | Y15: =if(W15=0,"",AA15/$AF$20) | Z15: =if(X15=0,"...",if(W15=0,"...",sumifs($N$2:$N97,$B$2:$B97,W15,$D$2:$D97,"ABIERTA")/X15)) -> ... | AA15: =if(W15=0,"...",sumifs($Q$2:$Q97,$B$2:$B97,W15,$D$2:$D97,"ABIERTA")) -> ... | AB15: =if(X15=0,"...",if(W15=0,"...",AC15/(AA15-AC15))) -> ... | AC15: =if(X15=0,"...",if(W15=0,"...",sumifs($S$2:$S97,$B$2:$B97,W15,$D$2:$D97,"ABIERTA"))) -> ...
A16: IOL | B16: KO | C16: 44715 | D16: ABIERTA | F16: =if($B16=0,"...", IF($E16=0,today()-$C16,$E16-$C16)) -> 1281 | G16: PESOS | H16: 18 | I16: 2670.7778 | K16: =IFERROR(__xludf.DUMMYFUNCTION("if(B16=0,""..."",GOOGLEFINANCE(""BCBA:""&B16))"),21220.0) -> 21220 | L16: =if(B16=0,"...",$H16*I16) -> 48074 | M16: =VLOOKUP(C16,CCLHistory!$A$3:$B84,2,FALSE) -> 209,39 | N16: =L16/IF(G16="USD",1,M16) -> 229.59072 | O16: =if(B16=0,"...",$H16*(IF(D16="ABIERTA",K16,J16)*(1-VLOOKUP(A16,Config!$A$3:$B$5,2,FALSE)))) -> 381940.9 | P16: =IF(D16="ABIERTA",Config!$D$4,VLOOKUP(E16,CCLHistory!$A$6:$B84,2,FALSE)) -> 1269 | Q16: =O16/IF(G16="USD",1,P16) -> 300.97786 | R16: =if(B16=0,"...",Q16/N16-1) -> 0.31093217 | S16: =if(B16=0,"...",Q16-N16) -> 71.38714 | T16: =if(B16=0,"...",O16/L16-1) -> 6.9448537 | U16: =if(B16=0,"...",O16-L16) -> 333866.9 | X16: =if(W16=0,"...",sumifs($H$2:$H98,$B$2:$B98,W16,$D$2:$D98,"ABIERTA")) -> ... | Y16: =if(W16=0,"",AA16/$AF$20) | Z16: =if(X16=0,"...",if(W16=0,"...",sumifs($N$2:$N98,$B$2:$B98,W16,$D$2:$D98,"ABIERTA")/X16)) -> ... | AA16: =if(W16=0,"...",sumifs($Q$2:$Q98,$B$2:$B98,W16,$D$2:$D98,"ABIERTA")) -> ... | AB16: =if(X16=0,"...",if(W16=0,"...",AC16/(AA16-AC16))) -> ... | AC16: =if(X16=0,"...",if(W16=0,"...",sumifs($S$2:$S98,$B$2:$B98,W16,$D$2:$D98,"ABIERTA"))) -> ...
A17: IOL | B17: KO | C17: 44789 | D17: ABIERTA | F17: =if($B17=0,"...", IF($E17=0,today()-$C17,$E17-$C17)) -> 1207 | G17: PESOS | H17: 8 | I17: 3654 | K17: =IFERROR(__xludf.DUMMYFUNCTION("if(B17=0,""..."",GOOGLEFINANCE(""BCBA:""&B17))"),21220.0) -> 21220 | L17: =if(B17=0,"...",$H17*I17) -> 29232 | M17: =VLOOKUP(C17,CCLHistory!$A$3:$B84,2,FALSE) -> 282,06 | N17: =L17/IF(G17="USD",1,M17) -> 103.63752 | O17: =if(B17=0,"...",$H17*(IF(D17="ABIERTA",K17,J17)*(1-VLOOKUP(A17,Config!$A$3:$B$5,2,FALSE)))) -> 169751.51 | P17: =IF(D17="ABIERTA",Config!$D$4,VLOOKUP(E17,CCLHistory!$A$6:$B84,2,FALSE)) -> 1269 | Q17: =O17/IF(G17="USD",1,P17) -> 133.76794 | R17: =if(B17=0,"...",Q17/N17-1) -> 0.2907288 | S17: =if(B17=0,"...",Q17-N17) -> 30.130413 | T17: =if(B17=0,"...",O17/L17-1) -> 4.8070441 | U17: =if(B17=0,"...",O17-L17) -> 140519.51 | X17: =if(W17=0,"...",sumifs($H$2:$H99,$B$2:$B99,W17,$D$2:$D99,"ABIERTA")) -> ... | Y17: =if(W17=0,"",AA17/$AF$20) | Z17: =if(X17=0,"...",if(W17=0,"...",sumifs($N$2:$N99,$B$2:$B99,W17,$D$2:$D99,"ABIERTA")/X17)) -> ... | AA17: =if(W17=0,"...",sumifs($Q$2:$Q99,$B$2:$B99,W17,$D$2:$D99,"ABIERTA")) -> ... | AB17: =if(X17=0,"...",if(W17=0,"...",AC17/(AA17-AC17))) -> ... | AC17: =if(X17=0,"...",if(W17=0,"...",sumifs($S$2:$S99,$B$2:$B99,W17,$D$2:$D99,"ABIERTA"))) -> ...
A18: IOL | B18: KO | C18: 45104 | D18: ABIERTA | F18: =if($B18=0,"...", IF($E18=0,today()-$C18,$E18-$C18)) -> 892 | G18: PESOS | H18: 15 | I18: 6395.1667 | K18: =IFERROR(__xludf.DUMMYFUNCTION("if(B18=0,""..."",GOOGLEFINANCE(""BCBA:""&B18))"),21220.0) -> 21220 | L18: =if(B18=0,"...",$H18*I18) -> 95927.5 | M18: =VLOOKUP(C18,CCLHistory!$A$3:$B84,2,FALSE) -> 509,74 | N18: =L18/IF(G18="USD",1,M18) -> 188.18908 | O18: =if(B18=0,"...",$H18*(IF(D18="ABIERTA",K18,J18)*(1-VLOOKUP(A18,Config!$A$3:$B$5,2,FALSE)))) -> 318284.09 | P18: =IF(D18="ABIERTA",Config!$D$4,VLOOKUP(E18,CCLHistory!$A$6:$B84,2,FALSE)) -> 1269 | Q18: =O18/IF(G18="USD",1,P18) -> 250.81488 | R18: =if(B18=0,"...",Q18/N18-1) -> 0.33278129 | S18: =if(B18=0,"...",Q18-N18) -> 62.625804 | T18: =if(B18=0,"...",O18/L18-1) -> 2.317965 | U18: =if(B18=0,"...",O18-L18) -> 222356.58 | X18: =if(W18=0,"...",sumifs($H$2:$H100,$B$2:$B100,W18,$D$2:$D100,"ABIERTA")) -> ... | Y18: =if(W18=0,"",AA18/$AF$20) | Z18: =if(X18=0,"...",if(W18=0,"...",sumifs($N$2:$N100,$B$2:$B100,W18,$D$2:$D100,"ABIERTA")/X18)) -> ... | AA18: =if(W18=0,"...",sumifs($Q$2:$Q100,$B$2:$B100,W18,$D$2:$D100,"ABIERTA")) -> ... | AB18: =if(X18=0,"...",if(W18=0,"...",AC18/(AA18-AC18))) -> ... | AC18: =if(X18=0,"...",if(W18=0,"...",sumifs($S$2:$S100,$B$2:$B100,W18,$D$2:$D100,"ABIERTA"))) -> ...
A19: IOL | B19: KO | C19: 45142 | D19: ABIERTA | F19: =if($B19=0,"...", IF($E19=0,today()-$C19,$E19-$C19)) -> 854 | G19: PESOS | H19: 6 | I19: 7053 | K19: =IFERROR(__xludf.DUMMYFUNCTION("if(B19=0,""..."",GOOGLEFINANCE(""BCBA:""&B19))"),21220.0) -> 21220 | L19: =if(B19=0,"...",$H19*I19) -> 42318 | M19: =VLOOKUP(C19,CCLHistory!$A$3:$B84,2,FALSE) -> 585,41 | N19: =L19/IF(G19="USD",1,M19) -> 72.287798 | O19: =if(B19=0,"...",$H19*(IF(D19="ABIERTA",K19,J19)*(1-VLOOKUP(A19,Config!$A$3:$B$5,2,FALSE)))) -> 127313.63 | P19: =IF(D19="ABIERTA",Config!$D$4,VLOOKUP(E19,CCLHistory!$A$6:$B84,2,FALSE)) -> 1269 | Q19: =O19/IF(G19="USD",1,P19) -> 100.32595 | R19: =if(B19=0,"...",Q19/N19-1) -> 0.38786842 | S19: =if(B19=0,"...",Q19-N19) -> 28.038154 | T19: =if(B19=0,"...",O19/L19-1) -> 2.0084984 | U19: =if(B19=0,"...",O19-L19) -> 84995.634 | X19: =if(W19=0,"...",sumifs($H$2:$H101,$B$2:$B101,W19,$D$2:$D101,"ABIERTA")) -> ... | Y19: =if(W19=0,"",AA19/$AF$20) | Z19: =if(X19=0,"...",if(W19=0,"...",sumifs($N$2:$N101,$B$2:$B101,W19,$D$2:$D101,"ABIERTA")/X19)) -> ... | AA19: =if(W19=0,"...",sumifs($Q$2:$Q101,$B$2:$B101,W19,$D$2:$D101,"ABIERTA")) -> ... | AB19: =if(X19=0,"...",if(W19=0,"...",AC19/(AA19-AC19))) -> ... | AC19: =if(X19=0,"...",if(W19=0,"...",sumifs($S$2:$S101,$B$2:$B101,W19,$D$2:$D101,"ABIERTA"))) -> ...
A20: IOL | B20: KO | C20: 45149 | D20: ABIERTA | F20: =if($B20=0,"...", IF($E20=0,today()-$C20,$E20-$C20)) -> 847 | G20: PESOS | H20: 3 | I20: 7365 | K20: =IFERROR(__xludf.DUMMYFUNCTION("if(B20=0,""..."",GOOGLEFINANCE(""BCBA:""&B20))"),21220.0) -> 21220 | L20: =if(B20=0,"...",$H20*I20) -> 22095 | M20: =VLOOKUP(C20,CCLHistory!$A$3:$B84,2,FALSE) -> 601,44 | N20: =L20/IF(G20="USD",1,M20) -> 36.736832 | O20: =if(B20=0,"...",$H20*(IF(D20="ABIERTA",K20,J20)*(1-VLOOKUP(A20,Config!$A$3:$B$5,2,FALSE)))) -> 63656.817 | P20: =IF(D20="ABIERTA",Config!$D$4,VLOOKUP(E20,CCLHistory!$A$6:$B84,2,FALSE)) -> 1269 | Q20: =O20/IF(G20="USD",1,P20) -> 50.162976 | R20: =if(B20=0,"...",Q20/N20-1) -> 0.36546823 | S20: =if(B20=0,"...",Q20-N20) -> 13.426145 | T20: =if(B20=0,"...",O20/L20-1) -> 1.8810508 | U20: =if(B20=0,"...",O20-L20) -> 41561.817 | X20: =if(W20=0,"...",sumifs($H$2:$H102,$B$2:$B102,W20,$D$2:$D102,"ABIERTA")) -> ... | Y20: =if(W20=0,"",AA20/$AF$20) | Z20: =if(X20=0,"...",if(W20=0,"...",sumifs($N$2:$N102,$B$2:$B102,W20,$D$2:$D102,"ABIERTA")/X20)) -> ... | AA20: =if(W20=0,"...",sumifs($Q$2:$Q102,$B$2:$B102,W20,$D$2:$D102,"ABIERTA")) -> ... | AB20: =if(X20=0,"...",if(W20=0,"...",AC20/(AA20-AC20))) -> ... | AC20: =if(X20=0,"...",if(W20=0,"...",sumifs($S$2:$S102,$B$2:$B102,W20,$D$2:$D102,"ABIERTA"))) -> ... | AE20: Total Abierto | AF20: =sumifs(Q2:Q84,D2:D84,"ABIERTA") -> 3650.6595 | AG20: Total Acumulado | AH20: =sum(Q2:Q84) -> 7398.3682
A21: IOL | B21: KO | C21: 45184 | D21: ABIERTA | F21: =if($B21=0,"...", IF($E21=0,today()-$C21,$E21-$C21)) -> 812 | G21: PESOS | H21: 11 | I21: 8678.5 | K21: =IFERROR(__xludf.DUMMYFUNCTION("if(B21=0,""..."",GOOGLEFINANCE(""BCBA:""&B21))"),21220.0) -> 21220 | L21: =if(B21=0,"...",$H21*I21) -> 95463.5 | M21: =VLOOKUP(C21,CCLHistory!$A$3:$B84,2,FALSE) -> 740,08 | N21: =L21/IF(G21="USD",1,M21) -> 128.99078 | O21: =if(B21=0,"...",$H21*(IF(D21="ABIERTA",K21,J21)*(1-VLOOKUP(A21,Config!$A$3:$B$5,2,FALSE)))) -> 233408.33 | P21: =IF(D21="ABIERTA",Config!$D$4,VLOOKUP(E21,CCLHistory!$A$6:$B84,2,FALSE)) -> 1269 | Q21: =O21/IF(G21="USD",1,P21) -> 183.93091 | R21: =if(B21=0,"...",Q21/N21-1) -> 0.4259229 | S21: =if(B21=0,"...",Q21-N21) -> 54.940129 | T21: =if(B21=0,"...",O21/L21-1) -> 1.4450007 | U21: =if(B21=0,"...",O21-L21) -> 137944.83 | X21: =if(W21=0,"...",sumifs($H$2:$H103,$B$2:$B103,W21,$D$2:$D103,"ABIERTA")) -> ... | Y21: =if(W21=0,"",AA21/$AF$20) | Z21: =if(X21=0,"...",if(W21=0,"...",sumifs($N$2:$N103,$B$2:$B103,W21,$D$2:$D103,"ABIERTA")/X21)) -> ... | AA21: =if(W21=0,"...",sumifs($Q$2:$Q103,$B$2:$B103,W21,$D$2:$D103,"ABIERTA")) -> ... | AB21: =if(X21=0,"...",if(W21=0,"...",AC21/(AA21-AC21))) -> ... | AC21: =if(X21=0,"...",if(W21=0,"...",sumifs($S$2:$S103,$B$2:$B103,W21,$D$2:$D103,"ABIERTA"))) -> ...
A22: IOL | B22: KO | C22: 45216 | D22: ABIERTA | F22: =if($B22=0,"...", IF($E22=0,today()-$C22,$E22-$C22)) -> 780 | G22: PESOS | H22: 4 | I22: 10057 | K22: =IFERROR(__xludf.DUMMYFUNCTION("if(B22=0,""..."",GOOGLEFINANCE(""BCBA:""&B22))"),21220.0) -> 21220 | L22: =if(B22=0,"...",$H22*I22) -> 40228 | M22: =VLOOKUP(C22,CCLHistory!$A$3:$B84,2,FALSE) -> 962,69 | N22: =L22/IF(G22="USD",1,M22) -> 41.787076 | O22: =if(B22=0,"...",$H22*(IF(D22="ABIERTA",K22,J22)*(1-VLOOKUP(A22,Config!$A$3:$B$5,2,FALSE)))) -> 84875.756 | P22: =IF(D22="ABIERTA",Config!$D$4,VLOOKUP(E22,CCLHistory!$A$6:$B84,2,FALSE)) -> 1269 | Q22: =O22/IF(G22="USD",1,P22) -> 66.883968 | R22: =if(B22=0,"...",Q22/N22-1) -> 0.60058983 | S22: =if(B22=0,"...",Q22-N22) -> 25.096893 | T22: =if(B22=0,"...",O22/L22-1) -> 1.1098677 | U22: =if(B22=0,"...",O22-L22) -> 44647.756 | X22: =if(W22=0,"...",sumifs($H$2:$H104,$B$2:$B104,W22,$D$2:$D104,"ABIERTA")) -> ... | Y22: =if(W22=0,"",AA22/$AF$20) | Z22: =if(X22=0,"...",if(W22=0,"...",sumifs($N$2:$N104,$B$2:$B104,W22,$D$2:$D104,"ABIERTA")/X22)) -> ... | AA22: =if(W22=0,"...",sumifs($Q$2:$Q104,$B$2:$B104,W22,$D$2:$D104,"ABIERTA")) -> ... | AB22: =if(X22=0,"...",if(W22=0,"...",AC22/(AA22-AC22))) -> ... | AC22: =if(X22=0,"...",if(W22=0,"...",sumifs($S$2:$S104,$B$2:$B104,W22,$D$2:$D104,"ABIERTA"))) -> ... | AE22: Ganancia Abierto | AF22: =sumifs(S2:S84,D2:D84,"ABIERTA") -> 1074.7897 | AG22: Ganancia Acumulada | AH22: =sum(S2:S84) -> 1121.3373
A23: IOL | B23: DISN | C23: 45104 | D23: CERRADA | E23: 45551 | F23: =if($B23=0,"...", IF($E23=0,today()-$C23,$E23-$C23)) -> 447 | G23: PESOS | H23: 25 | I23: 3818 | J23: 9510 | K23: =IFERROR(__xludf.DUMMYFUNCTION("if(B23=0,""..."",GOOGLEFINANCE(""BCBA:""&B23))"),13250.0) -> 13250 | L23: =if(B23=0,"...",$H23*I23) -> 95450 | M23: =VLOOKUP(C23,CCLHistory!$A$3:$B84,2,FALSE) -> 509,74 | N23: =L23/IF(G23="USD",1,M23) -> 187.25232 | O23: =if(B23=0,"...",$H23*(IF(D23="ABIERTA",K23,J23)*(1-VLOOKUP(A23,Config!$A$3:$B$5,2,FALSE)))) -> 237738.11 | P23: =IF(D23="ABIERTA",Config!$D$4,VLOOKUP(E23,CCLHistory!$A$6:$B84,2,FALSE)) -> 1238.0086 | Q23: =O23/IF(G23="USD",1,P23) -> 192.03268 | R23: =if(B23=0,"...",Q23/N23-1) -> 0.025528972 | S23: =if(B23=0,"...",Q23-N23) -> 4.7803593 | T23: =if(B23=0,"...",O23/L23-1) -> 1.4907084 | U23: =if(B23=0,"...",O23-L23) -> 142288.11 | X23: =if(W23=0,"...",sumifs($H$2:$H105,$B$2:$B105,W23,$D$2:$D105,"ABIERTA")) -> ... | Y23: =if(W23=0,"",AA23/$AF$20) | Z23: =if(X23=0,"...",if(W23=0,"...",sumifs($N$2:$N105,$B$2:$B105,W23,$D$2:$D105,"ABIERTA")/X23)) -> ... | AA23: =if(W23=0,"...",sumifs($Q$2:$Q105,$B$2:$B105,W23,$D$2:$D105,"ABIERTA")) -> ... | AB23: =if(X23=0,"...",if(W23=0,"...",AC23/(AA23-AC23))) -> ... | AC23: =if(X23=0,"...",if(W23=0,"...",sumifs($S$2:$S105,$B$2:$B105,W23,$D$2:$D105,"ABIERTA"))) -> ...
A24: IOL | B24: DISN | C24: 45303 | D24: CERRADA | E24: 45551 | F24: =if($B24=0,"...", IF($E24=0,today()-$C24,$E24-$C24)) -> 248 | G24: PESOS | H24: 8 | I24: 8448.5 | J24: 9510 | K24: =IFERROR(__xludf.DUMMYFUNCTION("if(B24=0,""..."",GOOGLEFINANCE(""BCBA:""&B24))"),13250.0) -> 13250 | L24: =if(B24=0,"...",$H24*I24) -> 67588 | M24: =VLOOKUP(C24,CCLHistory!$A$3:$B84,2,FALSE) -> 1136.65 | N24: =L24/IF(G24="USD",1,M24) -> 59.462455 | O24: =if(B24=0,"...",$H24*(IF(D24="ABIERTA",K24,J24)*(1-VLOOKUP(A24,Config!$A$3:$B$5,2,FALSE)))) -> 76076.196 | P24: =IF(D24="ABIERTA",Config!$D$4,VLOOKUP(E24,CCLHistory!$A$7:$B84,2,FALSE)) -> 1238.0086 | Q24: =O24/IF(G24="USD",1,P24) -> 61.450459 | R24: =if(B24=0,"...",Q24/N24-1) -> 0.033432918 | S24: =if(B24=0,"...",Q24-N24) -> 1.9880034 | T24: =if(B24=0,"...",O24/L24-1) -> 0.12558732 | U24: =if(B24=0,"...",O24-L24) -> 8488.196
A25: IOL | B25: DISN | C25: 45308 | D25: ABIERTA | F25: =if($B25=0,"...", IF($E25=0,today()-$C25,$E25-$C25)) -> 688 | G25: PESOS | H25: 6 | I25: 9737.5 | K25: =IFERROR(__xludf.DUMMYFUNCTION("if(B25=0,""..."",GOOGLEFINANCE(""BCBA:""&B25))"),13250.0) -> 13250 | L25: =if(B25=0,"...",$H25*I25) -> 58425 | M25: =VLOOKUP(C25,CCLHistory!$A$3:$B84,2,FALSE) -> 1273.34 | N25: =L25/IF(G25="USD",1,M25) -> 45.883268 | O25: =if(B25=0,"...",$H25*(IF(D25="ABIERTA",K25,J25)*(1-VLOOKUP(A25,Config!$A$3:$B$5,2,FALSE)))) -> 79496.025 | P25: =IF(D25="ABIERTA",Config!$D$4,VLOOKUP(E25,CCLHistory!$A$6:$B84,2,FALSE)) -> 1269 | Q25: =O25/IF(G25="USD",1,P25) -> 62.644622 | R25: =if(B25=0,"...",Q25/N25-1) -> 0.36530428 | S25: =if(B25=0,"...",Q25-N25) -> 16.761354 | T25: =if(B25=0,"...",O25/L25-1) -> 0.36065083 | U25: =if(B25=0,"...",O25-L25) -> 21071.025
A26: IOL | B26: DIA | C26: 44789 | D26: ABIERTA | F26: =if($B26=0,"...", IF($E26=0,today()-$C26,$E26-$C26)) -> 1207 | G26: PESOS | H26: 8 | I26: 6865 | K26: =IFERROR(__xludf.DUMMYFUNCTION("if(B26=0,""..."",GOOGLEFINANCE(""BCBA:""&B26))"),36140.0) -> 36140 | L26: =if(B26=0,"...",$H26*I26) -> 54920 | M26: =VLOOKUP(C26,CCLHistory!$A$3:$B84,2,FALSE) -> 282,06 | N26: =L26/IF(G26="USD",1,M26) -> 194.71035 | O26: =if(B26=0,"...",$H26*(IF(D26="ABIERTA",K26,J26)*(1-VLOOKUP(A26,Config!$A$3:$B$5,2,FALSE)))) -> 289105.54 | P26: =IF(D26="ABIERTA",Config!$D$4,VLOOKUP(E26,CCLHistory!$A$6:$B84,2,FALSE)) -> 1269 | Q26: =O26/IF(G26="USD",1,P26) -> 227.82155 | R26: =if(B26=0,"...",Q26/N26-1) -> 0.17005364 | S26: =if(B26=0,"...",Q26-N26) -> 33.111202 | T26: =if(B26=0,"...",O26/L26-1) -> 4.2641213 | U26: =if(B26=0,"...",O26-L26) -> 234185.54 | X26: =if(W26=0,"...",sumifs($H$2:$H84,$B$2:$B84,W26,$D$2:$D84,"ABIERTA")) -> ... | Y26: =if(W26=0,"",AA26/$AF$20) | Z26: =if(X26=0,"...",if(W26=0,"...",sumifs($N$2:$N84,$B$2:$B84,W26,$D$2:$D84,"ABIERTA")/X26)) -> ... | AA26: =if(W26=0,"...",sumifs($Q$2:$Q84,$B$2:$B84,W26,$D$2:$D84,"ABIERTA")) -> ... | AB26: =if(X26=0,"...",if(W26=0,"...",AC26/(AA26-AC26))) -> ... | AC26: =if(X26=0,"...",if(W26=0,"...",sumifs($S$2:$S84,$B$2:$B84,W26,$D$2:$D84,"ABIERTA"))) -> ... | AE26: (%) | AF26: =AF22/(AF20-AF22) -> 0.41725313 | AG26: (%) | AH26: =AH22/(AH20-AH22) -> 0.17864135
A27: IOL | B27: DIA | C27: 44840 | D27: CERRADA | E27: 45294 | F27: =if($B27=0,"...", IF($E27=0,today()-$C27,$E27-$C27)) -> 454 | G27: PESOS | H27: 4 | I27: 4647 | J27: 19424 | K27: =IFERROR(__xludf.DUMMYFUNCTION("if(B27=0,""..."",GOOGLEFINANCE(""BCBA:""&B27))"),36140.0) -> 36140 | L27: =if(B27=0,"...",$H27*I27) -> 18588 | M27: =VLOOKUP(C27,CCLHistory!$A$6:$B84,2,FALSE) -> 307,38 | N27: =L27/M27 -> 60.472379 | O27: =if(B27=0,"...",$H27*(IF(D27="ABIERTA",K27,J27)*(1-VLOOKUP(A27,Config!$A$3:$B$5,2,FALSE)))) -> 77692.115 | P27: 1029.75 | Q27: =O27/P27 -> 75.447551 | R27: =if(B27=0,"...",Q27/N27-1) -> 0.24763654 | S27: =if(B27=0,"...",Q27-N27) -> 14.975171 | T27: =if(B27=0,"...",O27/L27-1) -> 3.179692 | U27: =if(B27=0,"...",O27-L27) -> 59104.115 | X27: =if(W27=0,"...",sumifs($H$2:$H85,$B$2:$B85,W27,$D$2:$D85,"ABIERTA")) -> ... | Y27: =if(W27=0,"",AA27/$AF$20) | Z27: =if(X27=0,"...",if(W27=0,"...",sumifs($N$2:$N85,$B$2:$B85,W27,$D$2:$D85,"ABIERTA")/X27)) -> ... | AA27: =if(W27=0,"...",sumifs($Q$2:$Q85,$B$2:$B85,W27,$D$2:$D85,"ABIERTA")) -> ... | AB27: =if(X27=0,"...",if(W27=0,"...",AC27/(AA27-AC27))) -> ... | AC27: =if(X27=0,"...",if(W27=0,"...",sumifs($S$2:$S85,$B$2:$B85,W27,$D$2:$D85,"ABIERTA"))) -> ...
A28: IOL | B28: DIA | C28: 45104 | D28: ABIERTA | F28: =if($B28=0,"...", IF($E28=0,today()-$C28,$E28-$C28)) -> 892 | G28: PESOS | H28: 11 | I28: 8772.5 | K28: =IFERROR(__xludf.DUMMYFUNCTION("if(B28=0,""..."",GOOGLEFINANCE(""BCBA:""&B28))"),36140.0) -> 36140 | L28: =if(B28=0,"...",$H28*I28) -> 96497.5 | M28: =VLOOKUP(C28,CCLHistory!$A$3:$B84,2,FALSE) -> 509,74 | N28: =L28/IF(G28="USD",1,M28) -> 189.30729 | O28: =if(B28=0,"...",$H28*(IF(D28="ABIERTA",K28,J31)*(1-VLOOKUP(A28,Config!$A$3:$B$5,2,FALSE)))) -> 397520.12 | P28: =IF(D28="ABIERTA",Config!$D$4,VLOOKUP(E28,CCLHistory!$A$6:$B84,2,FALSE)) -> 1269 | Q28: =O28/IF(G28="USD",1,P28) -> 313.25463 | R28: =if(B28=0,"...",Q28/N28-1) -> 0.65474146 | S28: =if(B28=0,"...",Q28-N28) -> 123.94733 | T28: =if(B28=0,"...",O28/L28-1) -> 3.1194862 | U28: =if(B28=0,"...",O28-L28) -> 301022.62 | X28: =if(W28=0,"...",sumifs($H$2:$H86,$B$2:$B86,W28,$D$2:$D86,"ABIERTA")) -> ... | Y28: =if(W28=0,"",AA28/$AF$20) | Z28: =if(X28=0,"...",if(W28=0,"...",sumifs($N$2:$N86,$B$2:$B86,W28,$D$2:$D86,"ABIERTA")/X28)) -> ... | AA28: =if(W28=0,"...",sumifs($Q$2:$Q86,$B$2:$B86,W28,$D$2:$D86,"ABIERTA")) -> ... | AB28: =if(X28=0,"...",if(W28=0,"...",AC28/(AA28-AC28))) -> ... | AC28: =if(X28=0,"...",if(W28=0,"...",sumifs($S$2:$S86,$B$2:$B86,W28,$D$2:$D86,"ABIERTA"))) -> ...
A29: IOL | B29: SPY | C29: 45104 | D29: ABIERTA | F29: =if($B29=0,"...", IF($E29=0,today()-$C29,$E29-$C29)) -> 892 | G29: PESOS | H29: 4 | I29: 11285 | K29: =IFERROR(__xludf.DUMMYFUNCTION("if(B29=0,""..."",GOOGLEFINANCE(""BCBA:""&B29))"),51650.0) -> 51650 | L29: =if(B29=0,"...",$H29*I29) -> 45140 | M29: =VLOOKUP(C29,CCLHistory!$A$3:$B84,2,FALSE) -> 509,74 | N29: =L29/IF(G29="USD",1,M29) -> 88.55495 | O29: =if(B29=0,"...",$H29*(IF(D29="ABIERTA",K29,J29)*(1-VLOOKUP(A29,Config!$A$3:$B$5,2,FALSE)))) -> 206589.67 | P29: =IF(D29="ABIERTA",Config!$D$4,VLOOKUP(E29,CCLHistory!$A$6:$B84,2,FALSE)) -> 1269 | Q29: =O29/IF(G29="USD",1,P29) -> 162.79722 | R29: =if(B29=0,"...",Q29/N29-1) -> 0.83837514 | S29: =if(B29=0,"...",Q29-N29) -> 74.242269 | T29: =if(B29=0,"...",O29/L29-1) -> 3.5766431 | U29: =if(B29=0,"...",O29-L29) -> 161449.67 | X29: =if(W29=0,"...",sumifs($H$2:$H87,$B$2:$B87,W29,$D$2:$D87,"ABIERTA")) -> ... | Y29: =if(W29=0,"",AA29/$AF$20) | Z29: =if(X29=0,"...",if(W29=0,"...",sumifs($N$2:$N87,$B$2:$B87,W29,$D$2:$D87,"ABIERTA")/X29)) -> ... | AA29: =if(W29=0,"...",sumifs($Q$2:$Q87,$B$2:$B87,W29,$D$2:$D87,"ABIERTA")) -> ... | AB29: =if(X29=0,"...",if(W29=0,"...",AC29/(AA29-AC29))) -> ... | AC29: =if(X29=0,"...",if(W29=0,"...",sumifs($S$2:$S87,$B$2:$B87,W29,$D$2:$D87,"ABIERTA"))) -> ...
A30: IOL | B30: SPY | C30: 44789 | D30: ABIERTA | F30: =if($B30=0,"...", IF($E30=0,today()-$C30,$E30-$C30)) -> 1207 | G30: PESOS | H30: 6 | I30: 6045.4167 | K30: =IFERROR(__xludf.DUMMYFUNCTION("if(B30=0,""..."",GOOGLEFINANCE(""BCBA:""&B30))"),51650.0) -> 51650 | L30: =if(B30=0,"...",$H30*I30) -> 36272.5 | M30: =VLOOKUP(C30,CCLHistory!$A$3:$B84,2,FALSE) -> 282,06 | N30: =L30/IF(G30="USD",1,M30) -> 128.59853 | O30: =if(B30=0,"...",$H30*(IF(D30="ABIERTA",K30,J30)*(1-VLOOKUP(A30,Config!$A$3:$B$5,2,FALSE)))) -> 309884.51 | P30: =IF(D30="ABIERTA",Config!$D$4,VLOOKUP(E30,CCLHistory!$A$6:$B84,2,FALSE)) -> 1269 | Q30: =O30/IF(G30="USD",1,P30) -> 244.19583 | R30: =if(B30=0,"...",Q30/N30-1) -> 0.89890067 | S30: =if(B30=0,"...",Q30-N30) -> 115.5973 | T30: =if(B30=0,"...",O30/L30-1) -> 7.5432353 | U30: =if(B30=0,"...",O30-L30) -> 273612 | X30: =if(W30=0,"...",sumifs($H$2:$H88,$B$2:$B88,W30,$D$2:$D88,"ABIERTA")) -> ... | Y30: =if(W30=0,"",AA30/$AF$20) | Z30: =if(X30=0,"...",if(W30=0,"...",sumifs($N$2:$N88,$B$2:$B88,W30,$D$2:$D88,"ABIERTA")/X30)) -> ... | AA30: =if(W30=0,"...",sumifs($Q$2:$Q88,$B$2:$B88,W30,$D$2:$D88,"ABIERTA")) -> ... | AB30: =if(X30=0,"...",if(W30=0,"...",AC30/(AA30-AC30))) -> ... | AC30: =if(X30=0,"...",if(W30=0,"...",sumifs($S$2:$S88,$B$2:$B88,W30,$D$2:$D88,"ABIERTA"))) -> ...
A31: IOL | B31: SPY | C31: 44840 | D31: CERRADA | E31: 45294 | F31: =if($B31=0,"...", IF($E31=0,today()-$C31,$E31-$C31)) -> 454 | G31: PESOS | H31: 3 | I31: 5804.5 | J31: 24350 | K31: =IFERROR(__xludf.DUMMYFUNCTION("if(B31=0,""..."",GOOGLEFINANCE(""BCBA:""&B31))"),51650.0) -> 51650 | L31: =if(B31=0,"...",$H31*I31) -> 17413.5 | M31: =VLOOKUP(C31,CCLHistory!$A$6:$B84,2,FALSE) -> 307,38 | N31: =L31/M31 -> 56.651376 | O31: =if(B31=0,"...",$H31*(IF(D31="ABIERTA",K31,J31)*(1-VLOOKUP(A31,Config!$A$3:$B$5,2,FALSE)))) -> 73046.348 | P31: 1030 | Q31: =O31/P31 -> 70.918784 | R31: =if(B31=0,"...",Q31/N31-1) -> 0.25184574 | S31: =if(B31=0,"...",Q31-N31) -> 14.267408 | T31: =if(B31=0,"...",O31/L31-1) -> 3.1948114 | U31: =if(B31=0,"...",O31-L31) -> 55632.848 | X31: =if(W31=0,"...",sumifs($H$2:$H89,$B$2:$B89,W31,$D$2:$D89,"ABIERTA")) -> ... | Y31: =if(W31=0,"",AA31/$AF$20) | Z31: =if(X31=0,"...",if(W31=0,"...",sumifs($N$2:$N89,$B$2:$B89,W31,$D$2:$D89,"ABIERTA")/X31)) -> ... | AA31: =if(W31=0,"...",sumifs($Q$2:$Q89,$B$2:$B89,W31,$D$2:$D89,"ABIERTA")) -> ... | AB31: =if(X31=0,"...",if(W31=0,"...",AC31/(AA31-AC31))) -> ... | AC31: =if(X31=0,"...",if(W31=0,"...",sumifs($S$2:$S89,$B$2:$B89,W31,$D$2:$D89,"ABIERTA"))) -> ...
A32: IOL | B32: SPY | C32: 45020 | D32: CERRADA | E32: 45294 | F32: =if($B32=0,"...", IF($E32=0,today()-$C32,$E32-$C32)) -> 274 | G32: PESOS | H32: 5 | I32: 8278 | J32: 24350 | K32: =IFERROR(__xludf.DUMMYFUNCTION("if(B32=0,""..."",GOOGLEFINANCE(""BCBA:""&B32))"),51650.0) -> 51650 | L32: =if(B32=0,"...",$H32*I32) -> 41390 | M32: =VLOOKUP(C32,CCLHistory!$A$6:$B84,2,FALSE) -> 409,82 | N32: =L32/M32 -> 100.99556 | O32: =if(B32=0,"...",$H32*(IF(D32="ABIERTA",K32,J32)*(1-VLOOKUP(A32,Config!$A$3:$B$5,2,FALSE)))) -> 121743.91 | P32: 1030 | Q32: =O32/P32 -> 118.19797 | R32: =if(B32=0,"...",Q32/N32-1) -> 0.17032842 | S32: =if(B32=0,"...",Q32-N32) -> 17.202414 | T32: =if(B32=0,"...",O32/L32-1) -> 1.9413847 | U32: =if(B32=0,"...",O32-L32) -> 80353.913 | X32: =if(W32=0,"...",sumifs($H$2:$H90,$B$2:$B90,W32,$D$2:$D90,"ABIERTA")) -> ... | Y32: =if(W32=0,"",AA32/$AF$20) | Z32: =if(X32=0,"...",if(W32=0,"...",sumifs($N$2:$N90,$B$2:$B90,W32,$D$2:$D90,"ABIERTA")/X32)) -> ... | AA32: =if(W32=0,"...",sumifs($Q$2:$Q90,$B$2:$B90,W32,$D$2:$D90,"ABIERTA")) -> ... | AB32: =if(X32=0,"...",if(W32=0,"...",AC32/(AA32-AC32))) -> ... | AC32: =if(X32=0,"...",if(W32=0,"...",sumifs($S$2:$S90,$B$2:$B90,W32,$D$2:$D90,"ABIERTA"))) -> ...
A33: IOL | B33: AAPL | C33: 44148 | D33: CERRADA | E33: 44305 | F33: =if(B33=0,"...", IF(E33=0,today()-C33,E33-C33)) -> 157 | G33: PESOS | H33: 2 | I33: =1765*(1-VLOOKUP(A33,Config!A3:B5,2,FALSE)) -> 1764.9117 | J33: 2036 | K33: =IFERROR(__xludf.DUMMYFUNCTION("if(B33=0,""..."",GOOGLEFINANCE(""BCBA:""&B33))"),21040.0) -> 21040 | L33: =if(B33=0,"...",$H33*I33) -> 3529.8235 | M33: =VLOOKUP(C33,CCLHistory!$A$6:$B84,2,FALSE) -> 148,74 | N33: =L33/M33 -> 23.731501 | O33: =if(B33=0,"...",$H33*(IF(D33="ABIERTA",K33,J33)*(1-VLOOKUP(A33,Config!$A$3:$B$5,2,FALSE)))) -> 4071.7964 | P33: =IF(D33="ABIERTA",Config!$D$4,VLOOKUP(E33,CCLHistory!$A$6:$B84,2,FALSE)) -> 151,81 | Q33: =O33/P33 -> 26.821661 | R33: =if(B33=0,"...",Q33/N33-1) -> 0.13021342 | S33: =if(B33=0,"...",Q33-N33) -> 3.09016 | T33: =if(B33=0,"...",O33/L33-1) -> 0.15354108 | U33: =if(B33=0,"...",O33-L33) -> 541.9729 | X33: =if(W33=0,"...",sumifs($H$2:$H91,$B$2:$B91,W33,$D$2:$D91,"ABIERTA")) -> ... | Y33: =if(W33=0,"",AA33/$AF$20) | Z33: =if(X33=0,"...",if(W33=0,"...",sumifs($N$2:$N91,$B$2:$B91,W33,$D$2:$D91,"ABIERTA")/X33)) -> ... | AA33: =if(W33=0,"...",sumifs($Q$2:$Q91,$B$2:$B91,W33,$D$2:$D91,"ABIERTA")) -> ... | AB33: =if(X33=0,"...",if(W33=0,"...",AC33/(AA33-AC33))) -> ... | AC33: =if(X33=0,"...",if(W33=0,"...",sumifs($S$2:$S91,$B$2:$B91,W33,$D$2:$D91,"ABIERTA"))) -> ...
A34: IOL | B34: AAPL | C34: 44155 | D34: CERRADA | E34: 44799 | F34: =if(B34=0,"...", IF(E34=0,today()-C34,E34-C34)) -> 644 | G34: PESOS | H34: 2 | I34: =1805 -> 1805 | J34: 5030 | K34: =IFERROR(__xludf.DUMMYFUNCTION("if(B34=0,""..."",GOOGLEFINANCE(""BCBA:""&B34))"),21040.0) -> 21040 | L34: =if(B34=0,"...",$H34*I34) -> 3610 | M34: =VLOOKUP(C34,CCLHistory!$A$6:$B84,2,FALSE) -> 154,26 | N34: =L34/M34 -> 23.402048 | O34: =if(B34=0,"...",$H34*(IF(D34="ABIERTA",K34,J34)*(1-VLOOKUP(A34,Config!$A$3:$B$5,2,FALSE)))) -> 10059.497 | P34: =IF(D34="ABIERTA",Config!$D$4,VLOOKUP(E34,CCLHistory!$A$6:$B84,2,FALSE)) -> 289,2 | Q34: =O34/P34 -> 34.783876 | R34: =if(B34=0,"...",Q34/N34-1) -> 0.48636032 | S34: =if(B34=0,"...",Q34-N34) -> 11.381828 | T34: =if(B34=0,"...",O34/L34-1) -> 1.7865643 | U34: =if(B34=0,"...",O34-L34) -> 6449.497 | X34: =if(W34=0,"...",sumifs($H$2:$H92,$B$2:$B92,W34,$D$2:$D92,"ABIERTA")) -> ... | Y34: =if(W34=0,"",AA34/$AF$20) | Z34: =if(X34=0,"...",if(W34=0,"...",sumifs($N$2:$N92,$B$2:$B92,W34,$D$2:$D92,"ABIERTA")/X34)) -> ... | AA34: =if(W34=0,"...",sumifs($Q$2:$Q92,$B$2:$B92,W34,$D$2:$D92,"ABIERTA")) -> ... | AB34: =if(X34=0,"...",if(W34=0,"...",AC34/(AA34-AC34))) -> ... | AC34: =if(X34=0,"...",if(W34=0,"...",sumifs($S$2:$S92,$B$2:$B92,W34,$D$2:$D92,"ABIERTA"))) -> ...
A35: IOL | B35: AAPL | C35: 44334 | D35: CERRADA | E35: 44799 | F35: =if(B35=0,"...", IF(E35=0,today()-C35,E35-C35)) -> 465 | G35: PESOS | H35: 2 | I35: 1997 | J35: 5030 | K35: =IFERROR(__xludf.DUMMYFUNCTION("if(B35=0,""..."",GOOGLEFINANCE(""BCBA:""&B35))"),21040.0) -> 21040 | L35: =if(B35=0,"...",$H35*I35) -> 3994 | M35: =VLOOKUP(C35,CCLHistory!$A$6:$B84,2,FALSE) -> 162,45 | N35: =L35/M35 -> 24.586026 | O35: =if(B35=0,"...",$H35*(IF(D35="ABIERTA",K35,J35)*(1-VLOOKUP(A35,Config!$A$3:$B$5,2,FALSE)))) -> 10059.497 | P35: =IF(D35="ABIERTA",Config!$D$4,VLOOKUP(E35,CCLHistory!$A$6:$B84,2,FALSE)) -> 289,2 | Q35: =O35/P35 -> 34.783876 | R35: =if(B35=0,"...",Q35/N35-1) -> 0.41478235 | S35: =if(B35=0,"...",Q35-N35) -> 10.19785 | T35: =if(B35=0,"...",O35/L35-1) -> 1.5186522 | U35: =if(B35=0,"...",O35-L35) -> 6065.497 | X35: =if(W35=0,"...",sumifs($H$2:$H93,$B$2:$B93,W35,$D$2:$D93,"ABIERTA")) -> ... | Y35: =if(W35=0,"",AA35/$AF$20) | Z35: =if(X35=0,"...",if(W35=0,"...",sumifs($N$2:$N93,$B$2:$B93,W35,$D$2:$D93,"ABIERTA")/X35)) -> ... | AA35: =if(W35=0,"...",sumifs($Q$2:$Q93,$B$2:$B93,W35,$D$2:$D93,"ABIERTA")) -> ... | AB35: =if(X35=0,"...",if(W35=0,"...",AC35/(AA35-AC35))) -> ... | AC35: =if(X35=0,"...",if(W35=0,"...",sumifs($S$2:$S93,$B$2:$B93,W35,$D$2:$D93,"ABIERTA"))) -> ...
A36: IOL | B36: AAPL | C36: 44649 | D36: CERRADA | E36: 44799 | F36: =if(B36=0,"...", IF(E36=0,today()-C36,E36-C36)) -> 150 | G36: PESOS | H36: 5 | I36: 3490 | J36: 5030 | K36: =IFERROR(__xludf.DUMMYFUNCTION("if(B36=0,""..."",GOOGLEFINANCE(""BCBA:""&B36))"),21040.0) -> 21040 | L36: =if(B36=0,"...",$H36*I36) -> 17450 | M36: =VLOOKUP(C36,CCLHistory!$A$6:$B84,2,FALSE) -> 191,52 | N36: =L36/M36 -> 91.1132 | O36: =if(B36=0,"...",$H36*(IF(D36="ABIERTA",K36,J36)*(1-VLOOKUP(A36,Config!$A$3:$B$5,2,FALSE)))) -> 25148.743 | P36: =IF(D36="ABIERTA",Config!$D$4,VLOOKUP(E36,CCLHistory!$A$6:$B84,2,FALSE)) -> 289,2 | Q36: =O36/P36 -> 86.959691 | R36: =if(B36=0,"...",Q36/N36-1) -> -0.04558625 | S36: =if(B36=0,"...",Q36-N36) -> -4.1535091 | T36: =if(B36=0,"...",O36/L36-1) -> 0.44118868 | U36: =if(B36=0,"...",O36-L36) -> 7698.7425 | X36: =if(W36=0,"...",sumifs($H$2:$H94,$B$2:$B94,W36,$D$2:$D94,"ABIERTA")) -> ... | Y36: =if(W36=0,"",AA36/$AF$20) | Z36: =if(X36=0,"...",if(W36=0,"...",sumifs($N$2:$N94,$B$2:$B94,W36,$D$2:$D94,"ABIERTA")/X36)) -> ... | AA36: =if(W36=0,"...",sumifs($Q$2:$Q94,$B$2:$B94,W36,$D$2:$D94,"ABIERTA")) -> ... | AB36: =if(X36=0,"...",if(W36=0,"...",AC36/(AA36-AC36))) -> ... | AC36: =if(X36=0,"...",if(W36=0,"...",sumifs($S$2:$S94,$B$2:$B94,W36,$D$2:$D94,"ABIERTA"))) -> ...
A37: IOL | B37: AAPL | C37: 44687 | D37: CERRADA | E37: 44799 | F37: =if(B37=0,"...", IF(E37=0,today()-C37,E37-C37)) -> 112 | G37: PESOS | H37: 5 | I37: 3339.5 | J37: 5030 | K37: =IFERROR(__xludf.DUMMYFUNCTION("if(B37=0,""..."",GOOGLEFINANCE(""BCBA:""&B37))"),21040.0) -> 21040 | L37: =if(B37=0,"...",$H37*I37) -> 16697.5 | M37: =VLOOKUP(C37,CCLHistory!$A$6:$B84,2,FALSE) -> 208,84 | N37: =L37/M37 -> 79.953553 | O37: =if(B37=0,"...",$H37*(IF(D37="ABIERTA",K37,J37)*(1-VLOOKUP(A37,Config!$A$3:$B$5,2,FALSE)))) -> 25148.743 | P37: =IF(D37="ABIERTA",Config!$D$4,VLOOKUP(E37,CCLHistory!$A$6:$B84,2,FALSE)) -> 289,2 | Q37: =O37/P37 -> 86.959691 | R37: =if(B37=0,"...",Q37/N37-1) -> 0.087627595 | S37: =if(B37=0,"...",Q37-N37) -> 7.0061376 | T37: =if(B37=0,"...",O37/L37-1) -> 0.50613819 | U37: =if(B37=0,"...",O37-L37) -> 8451.2425 | X37: =if(W37=0,"...",sumifs($H$2:$H95,$B$2:$B95,W37,$D$2:$D95,"ABIERTA")) -> ... | Y37: =if(W37=0,"",AA37/$AF$20) | Z37: =if(X37=0,"...",if(W37=0,"...",sumifs($N$2:$N95,$B$2:$B95,W37,$D$2:$D95,"ABIERTA")/X37)) -> ... | AA37: =if(W37=0,"...",sumifs($Q$2:$Q95,$B$2:$B95,W37,$D$2:$D95,"ABIERTA")) -> ... | AB37: =if(X37=0,"...",if(W37=0,"...",AC37/(AA37-AC37))) -> ... | AC37: =if(X37=0,"...",if(W37=0,"...",sumifs($S$2:$S95,$B$2:$B95,W37,$D$2:$D95,"ABIERTA"))) -> ...
A38: IOL | B38: AAPL | C38: 44715 | D38: CERRADA | E38: 44799 | F38: =if(B38=0,"...", IF(E38=0,today()-C38,E38-C38)) -> 84 | G38: PESOS | H38: 3 | I38: 3160 | J38: 5030 | K38: =IFERROR(__xludf.DUMMYFUNCTION("if(B38=0,""..."",GOOGLEFINANCE(""BCBA:""&B38))"),21040.0) -> 21040 | L38: =if(B38=0,"...",$H38*I38) -> 9480 | M38: =VLOOKUP(C38,CCLHistory!$A$6:$B84,2,FALSE) -> 209,39 | N38: =L38/M38 -> 45.274368 | O38: =if(B38=0,"...",$H38*(IF(D38="ABIERTA",K38,J38)*(1-VLOOKUP(A38,Config!$A$3:$B$5,2,FALSE)))) -> 15089.246 | P38: =IF(D38="ABIERTA",Config!$D$4,VLOOKUP(E38,CCLHistory!$A$6:$B84,2,FALSE)) -> 289,2 | Q38: =O38/P38 -> 52.175814 | R38: =if(B38=0,"...",Q38/N38-1) -> 0.15243605 | S38: =if(B38=0,"...",Q38-N38) -> 6.9014459 | T38: =if(B38=0,"...",O38/L38-1) -> 0.59169256 | U38: =if(B38=0,"...",O38-L38) -> 5609.2455 | X38: =if(W38=0,"...",sumifs($H$2:$H96,$B$2:$B96,W38,$D$2:$D96,"ABIERTA")) -> ... | Y38: =if(W38=0,"",AA38/$AF$20) | Z38: =if(X38=0,"...",if(W38=0,"...",sumifs($N$2:$N96,$B$2:$B96,W38,$D$2:$D96,"ABIERTA")/X38)) -> ... | AA38: =if(W38=0,"...",sumifs($Q$2:$Q96,$B$2:$B96,W38,$D$2:$D96,"ABIERTA")) -> ... | AB38: =if(X38=0,"...",if(W38=0,"...",AC38/(AA38-AC38))) -> ... | AC38: =if(X38=0,"...",if(W38=0,"...",sumifs($S$2:$S96,$B$2:$B96,W38,$D$2:$D96,"ABIERTA"))) -> ...
A39: IOL | B39: AAPL | C39: 44715 | D39: CERRADA | E39: 44811 | F39: =if(B39=0,"...", IF(E39=0,today()-C39,E39-C39)) -> 96 | G39: PESOS | H39: 6 | I39: 3160 | J39: 4449.5 | K39: =IFERROR(__xludf.DUMMYFUNCTION("if(B39=0,""..."",GOOGLEFINANCE(""BCBA:""&B39))"),21040.0) -> 21040 | L39: =if(B39=0,"...",$H39*I39) -> 18960 | M39: =VLOOKUP(C39,CCLHistory!$A$6:$B84,2,FALSE) -> 209,39 | N39: =L39/M39 -> 90.548737 | O39: =if(B39=0,"...",$H39*(IF(D39="ABIERTA",K39,J39)*(1-VLOOKUP(A39,Config!$A$3:$B$5,2,FALSE)))) -> 26695.665 | P39: =IF(D39="ABIERTA",Config!$D$4,VLOOKUP(E39,CCLHistory!$A$6:$B84,2,FALSE)) -> 282,46 | Q39: =O39/P39 -> 94.511312 | R39: =if(B39=0,"...",Q39/N39-1) -> 0.043761793 | S39: =if(B39=0,"...",Q39-N39) -> 3.9625751 | T39: =if(B39=0,"...",O39/L39-1) -> 0.40799922 | U39: =if(B39=0,"...",O39-L39) -> 7735.6651 | X39: =if(W39=0,"...",sumifs($H$2:$H97,$B$2:$B97,W39,$D$2:$D97,"ABIERTA")) -> ... | Y39: =if(W39=0,"",AA39/$AF$20) | Z39: =if(X39=0,"...",if(W39=0,"...",sumifs($N$2:$N97,$B$2:$B97,W39,$D$2:$D97,"ABIERTA")/X39)) -> ... | AA39: =if(W39=0,"...",sumifs($Q$2:$Q97,$B$2:$B97,W39,$D$2:$D97,"ABIERTA")) -> ... | AB39: =if(X39=0,"...",if(W39=0,"...",AC39/(AA39-AC39))) -> ... | AC39: =if(X39=0,"...",if(W39=0,"...",sumifs($S$2:$S97,$B$2:$B97,W39,$D$2:$D97,"ABIERTA"))) -> ...
A40: IOL | B40: AAPL | C40: 44777 | D40: CERRADA | E40: 44811 | F40: =if(B40=0,"...", IF(E40=0,today()-C40,E40-C40)) -> 34 | G40: PESOS | H40: 6 | I40: 4616 | J40: 4449.5 | K40: =IFERROR(__xludf.DUMMYFUNCTION("if(B40=0,""..."",GOOGLEFINANCE(""BCBA:""&B40))"),21040.0) -> 21040 | L40: =if(B40=0,"...",$H40*I40) -> 27696 | M40: =VLOOKUP(C40,CCLHistory!$A$6:$B84,2,FALSE) -> 293,31 | N40: =L40/M40 -> 94.425693 | O40: =if(B40=0,"...",$H40*(IF(D40="ABIERTA",K40,J40)*(1-VLOOKUP(A40,Config!$A$3:$B$5,2,FALSE)))) -> 26695.665 | P40: =IF(D40="ABIERTA",Config!$D$4,VLOOKUP(E40,CCLHistory!$A$6:$B84,2,FALSE)) -> 282,46 | Q40: =O40/P40 -> 94.511312 | R40: =if(B40=0,"...",Q40/N40-1) -> 0.00090673324 | S40: =if(B40=0,"...",Q40-N40) -> 0.085618914 | T40: =if(B40=0,"...",O40/L40-1) -> -0.036118387 | U40: =if(B40=0,"...",O40-L40) -> -1000.3348 | X40: =if(W40=0,"...",sumifs($H$2:$H98,$B$2:$B98,W40,$D$2:$D98,"ABIERTA")) -> ... | Y40: =if(W40=0,"",AA40/$AF$20) | Z40: =if(X40=0,"...",if(W40=0,"...",sumifs($N$2:$N98,$B$2:$B98,W40,$D$2:$D98,"ABIERTA")/X40)) -> ... | AA40: =if(W40=0,"...",sumifs($Q$2:$Q98,$B$2:$B98,W40,$D$2:$D98,"ABIERTA")) -> ... | AB40: =if(X40=0,"...",if(W40=0,"...",AC40/(AA40-AC40))) -> ... | AC40: =if(X40=0,"...",if(W40=0,"...",sumifs($S$2:$S98,$B$2:$B98,W40,$D$2:$D98,"ABIERTA"))) -> ...
...

Sheet ONs
B1: 10/30/23 | C1: Apertura | D1: Estado | E1: Cierre | F1: Dias | G1: Moneda | H1: Unidades | I1: Valor Compra | J1: Valor Venta | K1: Valor Actual | L1: Valor Actual USD | M1: Total Compra | N1: MEP Compra | O1: TC USD | P1: Total Venta | Q1: MEP Venta | R1: TV USD | S1: Ganancias (%) | T1: Ganancias Bruta | U1: GAN USD% | V1: GAN USD | X1: Ticker | Y1: Valor Actual | Z1: Unidades | AA1: % Cartera | AB1: PPC | AC1: Total (Abierto) | AD1: Ganancias (%) | AE1: Ganancias Tot | AL1: ONs
A2: IOL | B2: MTCGO | C2: 45126 | D2: ABIERTA | F2: =if(B2=0,"...", IF(E2=0,today()-C2,E2-C2)) -> 870 | G2: PESOS | H2: 362 | I2: 54149.903 | K2: =if(B2=0,"...",VLOOKUP(B2,$X$2:$Y1095,2,false)) -> 153140 | L2: =if(B2=0,"...",K2/IF(G2="DOLARES",1,Q2)) -> 120.92546 | M2: =if(B2=0,"...",$H2*I2/IF(G2="DOLARES",1,100)) -> 196022.65 | N2: =IF($F3=0,Config!$D$3,VLOOKUP(C3,MEPHistory!$A$3:$B1095,2,FALSE)) -> 505,75 | O2: =M2/IF(G2="DOLARES",1,N2) -> 387.58804 | P2: =if(B2=0,"...",$H2*(IF(D2="ABIERTA",K2,J2)*(1-VLOOKUP(A2,Config!$A$3:$B$5,2,FALSE)))/IF(G2="DOLARES",1,100)) -> 554339.08 | Q2: =IF(D2="ABIERTA",Config!$D$3,VLOOKUP(E2,CCLHistory!$A$6:$B1095,2,FALSE)) -> 1266.4 | R2: =P2/IF(G2="DOLARES",1,Q2) -> 437.72827 | S2: =if(B2=0,"...",P2/M2-1) -> 1.8279338 | T2: =if(B2=0,"...",P2-M2) -> 358316.43 | U2: =if(B2=0,"...",R2/O2-1) -> 0.12936476 | V2: =if(B2=0,"...",R2-O2) -> 50.140233 | X2: {=Unique(B2:B1095)} -> MTCGO | Y2: =if(X2=0,"...",VLOOKUP("*"&X2&"*",$AL$2:$AM1095,2,false)) -> 153140 | Z2: =if(X2=0,"...",sumifs($H$2:$H1095,$B$2:$B1095,X2,$D$2:$D1095,"ABIERTA")) -> 362 | AA2: =if(X2=0,"",AC2/$AH$18) -> 0.28537692 | AB2: =if(Z2=0,"...",if(X2=0,"...",sumifs($O$2:$O1095,$B$2:$B1095,X2,$D$2:$D1095,"ABIERTA")/Z2)) -> 1.0706852 | AC2: =if(X2=0,"...",sumifs($R$2:$R1095,$B$2:$B1095,X2,$D$2:$D1095,"ABIERTA")) -> 437.72827 | AD2: =if(Z2=0,"...",if(X2=0,"...",AE2/(AC2-AE2))) -> 0.12936476 | AE2: =if(Z2=0,"...",if(X2=0,"...",sumifs($V$2:$V1095,$B$2:$B1095,X2,$D$2:$D1095,"ABIERTA"))) -> 50.140233 | AL2: =IFERROR(__xludf.DUMMYFUNCTION("QUERY(IMPORTHTML(DataImports!B6,DataImports!D6,1),""select Col1, Col2"",1)"),"Símbolo") -> Símbolo | AM2: =IFERROR(__xludf.DUMMYFUNCTION("""COMPUTED_VALUE"""),"Último Operado") -> Último Operado
A3: IOL | B3: IRCFO | C3: 45134 | D3: ABIERTA | F3: =if(B3=0,"...", IF(E3=0,today()-C3,E3-C3)) -> 862 | G3: PESOS | H3: 363 | I3: 53888.567 | K3: =if(B3=0,"...",VLOOKUP(B3,$X$2:$Y1096,2,false)) -> 103540 | L3: =if(B3=0,"...",K3/IF(G3="DOLARES",1,Q3)) -> 81.759318 | M3: =if(B3=0,"...",$H3*I3/IF(G3="DOLARES",1,100)) -> 195615.5 | N3: =IF($F4=0,Config!$D$3,VLOOKUP(C4,MEPHistory!$A$3:$B1095,2,FALSE)) -> 509,94 | O3: =M3/IF(G3="DOLARES",1,N3) -> 383.60493 | P3: =if(B3=0,"...",$H3*(IF(D3="ABIERTA",K3,J3)*(1-VLOOKUP(A3,Config!$A$3:$B$5,2,FALSE)))/IF(G3="DOLARES",1,100)) -> 375831.41 | Q3: =IF(D3="ABIERTA",Config!$D$3,VLOOKUP(E3,CCLHistory!$A$6:$B1095,2,FALSE)) -> 1266.4 | R3: =P3/IF(G3="DOLARES",1,Q3) -> 296.77148 | S3: =if(B3=0,"...",P3/M3-1) -> 0.92127622 | T3: =if(B3=0,"...",P3-M3) -> 180215.91 | U3: =if(B3=0,"...",R3/O3-1) -> -0.22636166 | V3: =if(B3=0,"...",R3-O3) -> -86.83345 | X3: IRCFO | Y3: =if(X3=0,"...",VLOOKUP("*"&X3&"*",$AL$2:$AM1096,2,false)) -> 103540 | Z3: =if(X3=0,"...",sumifs($H$2:$H1096,$B$2:$B1096,X3,$D$2:$D1096,"ABIERTA")) -> 418 | AA3: =if(X3=0,"",AC3/$AH$18) -> 0.22279533 | AB3: =if(Z3=0,"...",if(X3=0,"...",sumifs($O$2:$O1096,$B$2:$B1096,X3,$D$2:$D1096,"ABIERTA")/Z3)) -> 1.0099004 | AC3: =if(X3=0,"...",sumifs($R$2:$R1096,$B$2:$B1096,X3,$D$2:$D1096,"ABIERTA")) -> 341.73686 | AD3: =if(Z3=0,"...",if(X3=0,"...",AE3/(AC3-AE3))) -> -0.19046246 | AE3: =if(Z3=0,"...",if(X3=0,"...",sumifs($V$2:$V1096,$B$2:$B1096,X3,$D$2:$D1096,"ABIERTA"))) -> -80.401515 | AL3: =IFERROR(__xludf.DUMMYFUNCTION("""COMPUTED_VALUE"""),"* AER1O *") -> * AER1O * | AM3: =IFERROR(__xludf.DUMMYFUNCTION("""COMPUTED_VALUE"""),15390.4) -> 15390.4
A4: IOL | B4: YMCIO | C4: 45135 | D4: ABIERTA | F4: =if(B4=0,"...", IF(E4=0,today()-C4,E4-C4)) -> 861 | G4: PESOS | H4: 375 | I4: 53229 | K4: =if(B4=0,"...",VLOOKUP(B4,$X$2:$Y1097,2,false)) -> 161330 | L4: =if(B4=0,"...",K4/IF(G4="DOLARES",1,Q4)) -> 127.39261 | M4: =if(B4=0,"...",$H4*I4/IF(G4="DOLARES",1,100)) -> 199608.75 | N4: =IF($F5=0,Config!$D$3,VLOOKUP(C5,MEPHistory!$A$3:$B1095,2,FALSE)) -> 899,33 | O4: =M4/IF(G4="DOLARES",1,N4) -> 221.95273 | P4: =if(B4=0,"...",$H4*(IF(D4="ABIERTA",K4,J4)*(1-VLOOKUP(A4,Config!$A$3:$B$5,2,FALSE)))/IF(G4="DOLARES",1,100)) -> 604957.25 | Q4: =IF(D4="ABIERTA",Config!$D$3,VLOOKUP(E4,CCLHistory!$A$6:$B1095,2,FALSE)) -> 1266.4 | R4: =P4/IF(G4="DOLARES",1,Q4) -> 477.6984 | S4: =if(B4=0,"...",P4/M4-1) -> 2.0307151 | T4: =if(B4=0,"...",P4-M4) -> 405348.5 | U4: =if(B4=0,"...",R4/O4-1) -> 1.1522528 | V4: =if(B4=0,"...",R4-O4) -> 255.74567 | X4: YMCIO | Y4: =if(X4=0,"...",VLOOKUP("*"&X4&"*",$AL$2:$AM1097,2,false)) -> 161330 | Z4: =if(X4=0,"...",sumifs($H$2:$H1097,$B$2:$B1097,X4,$D$2:$D1097,"ABIERTA")) -> 505 | AA4: =if(X4=0,"",AC4/$AH$18) -> 0.41939973 | AB4: =if(Z4=0,"...",if(X4=0,"...",sumifs($O$2:$O1097,$B$2:$B1097,X4,$D$2:$D1097,"ABIERTA")/Z4)) -> 0.6777955 | AC4: =if(X4=0,"...",sumifs($R$2:$R1097,$B$2:$B1097,X4,$D$2:$D1097,"ABIERTA")) -> 643.30051 | AD4: =if(Z4=0,"...",if(X4=0,"...",AE4/(AC4-AE4))) -> 0.87941995 | AE4: =if(Z4=0,"...",if(X4=0,"...",sumifs($V$2:$V1097,$B$2:$B1097,X4,$D$2:$D1097,"ABIERTA"))) -> 301.01378 | AL4: =IFERROR(__xludf.DUMMYFUNCTION("""COMPUTED_VALUE"""),"* AER9O *") -> * AER9O * | AM4: =IFERROR(__xludf.DUMMYFUNCTION("""COMPUTED_VALUE"""),150000.0) -> 150000
A5: IOL | B5: YMCID | C5: 45222 | D5: ABIERTA | F5: =if(B5=0,"...", IF(E5=0,today()-C5,E5-C5)) -> 774 | G5: DOLARES | H5: 1 | I5: 97.9 | K5: =if(B5=0,"...",VLOOKUP(B5,$X$2:$Y1098,2,false)) -> 111.1 | L5: =if(B5=0,"...",K5/IF(G5="DOLARES",1,Q5)) -> 111.1 | M5: =if(B5=0,"...",$H5*I5/IF(G5="DOLARES",1,100)) -> 97.9 | N5: =IF($F6=0,Config!$D$3,VLOOKUP(C6,MEPHistory!$A$3:$B1095,2,FALSE)) -> 857,14 | O5: =M5/IF(G5="DOLARES",1,N5) -> 97.9 | P5: =if(B5=0,"...",$H5*(IF(D5="ABIERTA",K5,J5)*(1-VLOOKUP(A5,Config!$A$3:$B$5,2,FALSE)))/IF(G5="DOLARES",1,100)) -> 111.09444 | Q5: =IF(D5="ABIERTA",Config!$D$3,VLOOKUP(E5,CCLHistory!$A$6:$B1095,2,FALSE)) -> 1266.4 | R5: =P5/IF(G5="DOLARES",1,Q5) -> 111.09444 | S5: =if(B5=0,"...",P5/M5-1) -> 0.13477472 | T5: =if(B5=0,"...",P5-M5) -> 13.194445 | U5: =if(B5=0,"...",R5/O5-1) -> 0.13477472 | V5: =if(B5=0,"...",R5-O5) -> 13.194445 | X5: YMCID | Y5: =if(X5=0,"...",VLOOKUP("*"&X5&"*",$AL$2:$AM1098,2,false)) -> 111.1 | Z5: =if(X5=0,"...",sumifs($H$2:$H1098,$B$2:$B1098,X5,$D$2:$D1098,"ABIERTA")) -> 1 | AA5: =if(X5=0,"",AC5/$AH$18) -> 0.072428017 | AB5: =if(Z5=0,"...",if(X5=0,"...",sumifs($O$2:$O1098,$B$2:$B1098,X5,$D$2:$D1098,"ABIERTA")/Z5)) -> 97.9 | AC5: =if(X5=0,"...",sumifs($R$2:$R1098,$B$2:$B1098,X5,$D$2:$D1098,"ABIERTA")) -> 111.09444 | AD5: =if(Z5=0,"...",if(X5=0,"...",AE5/(AC5-AE5))) -> 0.13477472 | AE5: =if(Z5=0,"...",if(X5=0,"...",sumifs($V$2:$V1098,$B$2:$B1098,X5,$D$2:$D1098,"ABIERTA"))) -> 13.194445 | AL5: =IFERROR(__xludf.DUMMYFUNCTION("""COMPUTED_VALUE"""),"* AERBD *") -> * AERBD * | AM5: =IFERROR(__xludf.DUMMYFUNCTION("""COMPUTED_VALUE"""),102.0) -> 102
